Workbook

Sheet हिन्दी
A1: KENDRIYA VIDYALAYA NIT AGARTALA | F1: KENDRIYA VIDYALAYA NIT AGARTALA
A2: SESSION : 2025-26 | F2: SESSION : 2025-26
B3: MARK-STATEMENT | D3: SSE | G3: MARK-STATEMENT | I3: SSE
A4: Class : VI | F4: Class : VI
A5: Subject: Hindi | F5: Subject: Hindi
A6: No. of Ans. Book : 41 | B6: 42 | F6: No. of Ans. Book : 41 | G6: 42
A7: Name of Examiner : Ms Susmita Dey | F7: Name of Examiner : Ms Susmita Dey
A8: Roll | B8: Name | C8: Marks | D8: % Marks | F8: Roll | G8: Name | H8: Marks | I8: % Marks
C9: 60 | H9: 60
A10: 1 | B10: ALIA AKTAR | C10: 21 | D10: =IF(UPPER(C10)="AB","AB",ROUND(((C10/C$9)*100),0)) -> 35 | F10: 1 | G10: ALIA AKTAR | H10: =C10 -> 21 | I10: =IF(UPPER(H10)="AB","AB",ROUND(((H10/H$9)*100),0)) -> 35
A11: 2 | B11: ANUSHA V | C11: 41 | D11: =IF(UPPER(C11)="AB","AB",ROUND(((C11/C$9)*100),0)) -> 68 | F11: 2 | G11: ANUSHA V | H11: =C11 -> 41 | I11: =IF(UPPER(H11)="AB","AB",ROUND(((H11/H$9)*100),0)) -> 68
A12: 3 | B12: ANUSHREE BEHERA | C12: 52 | D12: =IF(UPPER(C12)="AB","AB",ROUND(((C12/C$9)*100),0)) -> 87 | F12: 3 | G12: ANUSHREE BEHERA | H12: =C12 -> 52 | I12: =IF(UPPER(H12)="AB","AB",ROUND(((H12/H$9)*100),0)) -> 87
A13: 4 | B13: ARNESHA DEBNATH | C13: 51 | D13: =IF(UPPER(C13)="AB","AB",ROUND(((C13/C$9)*100),0)) -> 85 | F13: 4 | G13: ARNESHA DEBNATH | H13: =C13 -> 51 | I13: =IF(UPPER(H13)="AB","AB",ROUND(((H13/H$9)*100),0)) -> 85
A14: 5 | B14: ARSALA KHATUN | C14: 45 | D14: =IF(UPPER(C14)="AB","AB",ROUND(((C14/C$9)*100),0)) -> 75 | F14: 5 | G14: ARSALA KHATUN | H14: =C14 -> 45 | I14: =IF(UPPER(H14)="AB","AB",ROUND(((H14/H$9)*100),0)) -> 75
A15: 6 | B15: BAISHALI DEBNATH | C15: 36 | D15: =IF(UPPER(C15)="AB","AB",ROUND(((C15/C$9)*100),0)) -> 60 | F15: 6 | G15: BAISHALI DEBNATH | H15: =C15 -> 36 | I15: =IF(UPPER(H15)="AB","AB",ROUND(((H15/H$9)*100),0)) -> 60
A16: 7 | B16: BIPASHA DEBNATH | C16: 49 | D16: =IF(UPPER(C16)="AB","AB",ROUND(((C16/C$9)*100),0)) -> 82 | F16: 7 | G16: BIPASHA DEBNATH | H16: =C16 -> 49 | I16: =IF(UPPER(H16)="AB","AB",ROUND(((H16/H$9)*100),0)) -> 82
A17: 8 | B17: CHANDRA DAS | C17: 13 | D17: =IF(UPPER(C17)="AB","AB",ROUND(((C17/C$9)*100),0)) -> 22 | F17: 8 | G17: CHANDRA DAS | H17: =C17 -> 13 | I17: =IF(UPPER(H17)="AB","AB",ROUND(((H17/H$9)*100),0)) -> 22
A18: 9 | B18: JENISHA DEBBARMA | C18: 30 | D18: =IF(UPPER(C18)="AB","AB",ROUND(((C18/C$9)*100),0)) -> 50 | F18: 9 | G18: JENISHA DEBBARMA | H18: =C18 -> 30 | I18: =IF(UPPER(H18)="AB","AB",ROUND(((H18/H$9)*100),0)) -> 50
A19: 10 | B19: JIYA DEBBARMA | C19: 12 | D19: =IF(UPPER(C19)="AB","AB",ROUND(((C19/C$9)*100),0)) -> 20 | F19: 10 | G19: JIYA DEBBARMA | H19: =C19 -> 12 | I19: =IF(UPPER(H19)="AB","AB",ROUND(((H19/H$9)*100),0)) -> 20
A20: 11 | B20: JOYDIPA DAS | C20: 6 | D20: =IF(UPPER(C20)="AB","AB",ROUND(((C20/C$9)*100),0)) -> 10 | F20: 11 | G20: JOYDIPA DAS | H20: =C20 -> 6 | I20: =IF(UPPER(H20)="AB","AB",ROUND(((H20/H$9)*100),0)) -> 10
A21: 12 | B21: MAITRI MAJUMDER | C21: 34 | D21: =IF(UPPER(C21)="AB","AB",ROUND(((C21/C$9)*100),0)) -> 57 | F21: 12 | G21: MAITRI MAJUMDER | H21: =C21 -> 34 | I21: =IF(UPPER(H21)="AB","AB",ROUND(((H21/H$9)*100),0)) -> 57
... A51: 42 | B51: SUMANTA DEBBARMA | C51: 38 | D51: =IF(UPPER(C51)="AB","AB",ROUND(((C51/C$9)*100),0)) -> 63 | F51: 42 | G51: SUMANTA DEBBARMA | H51: =C51 -> 38 | I51: =IF(UPPER(H51)="AB","AB",ROUND(((H51/H$9)*100),0)) -> 63
D58: *AB-Absent | I58: *AB-Absent
A59: % Marks [Result Analysis] | F59: % Marks [Result Analysis]
A60: 90=< | B60: =COUNTIF(D10:D57,">=90") -> 4 | C60: Appered | D60: =COUNT(H10:H57) -> 42 | F60: 90=< | G60: =COUNTIF(I10:I57,">=90") -> 4 | H60: Appered | I60: =COUNT(H10:H57) -> 42
A61: 75-89.9 | B61: =COUNTIF(D10:D57,">=75")-B60 -> 8 | C61: Absent | D61: =COUNTIF(D10:D57,"=AB") -> 0 | F61: 75-89.9 | G61: =COUNTIF(I10:I57,">=75")-G60 -> 8 | H61: Absent | I61: =COUNTIF(I10:I57,"=AB") -> 0
A62: 60-74.9 | B62: =COUNTIF(D10:D57,">=60")-B61-B60 -> 8 | C62: Passed | D62: =COUNTIF(D10:D57,">=33") -> 31 | F62: 60-74.9 | G62: =COUNTIF(I10:I57,">=60")-G61-G60 -> 8 | H62: Passed | I62: =COUNTIF(I10:I57,">=33") -> 31
A63: 45-59.9 | B63: =COUNTIF(D10:D57,">=45")-B62-B61-B60 -> 8 | C63: Pass % | D63: =(D62/D60)*100 -> 73.809524 | F63: 45-59.9 | G63: =COUNTIF(I10:I57,">=45")-G62-G61-G60 -> 8 | H63: Pass % | I63: =(I62/I60)*100 -> 73.809524
A64: 33-44.9 | B64: =COUNTIF(D10:D57,">=33")-B63-B62-B61-B60 -> 3 | F64: 33-44.9 | G64: =COUNTIF(I10:I57,">=33")-G63-G62-G61-G60 -> 3
A65: <33 | B65: =COUNTIF(D10:D57,"<33")-COUNTIF(D10:D57,"=0.0") -> 11 | F65: <33 | G65: =COUNTIF(I10:I57,"<33")-COUNTIF(I10:I57,"=0.0") -> 11
A67: Sign. of Examiner_________________ | F67: Sign. of Examiner_________________
A68: Sign. of Checker_________________ | D68: Principal | F68: Sign. of Checker_________________ | I68: Principal

Sheet English
A1: KENDRIYA VIDYALAYA NIT AGARTALA | F1: KENDRIYA VIDYALAYA NIT AGARTALA
A2: SESSION : 2025-26 | F2: SESSION : 2025-26
B3: MARK-STATEMENT | D3: PT 2 | G3: MARK-STATEMENT | I3: PT 2
A4: Class : VI | F4: Class : VI
A5: Subject: ENGLISH | F5: Subject: ENGLISH
A6: No. of Ans. Book : 41 | F6: No. of Ans. Book : 41
A7: Name of Examiner : Ms. Saswati Das | F7: Name of Examiner : Ms. Saswati Das
A8: Roll | B8: Name | C8: Marks | D8: % Marks | F8: Roll | G8: Name | H8: Marks | I8: % Marks
C9: 40 | H9: 40
A10: 1 | B10: ALIA AKTAR | C10: 27 | D10: =IF(UPPER(C10)="AB","AB",ROUND(((C10/C$9)*100),0)) -> 68 | F10: 1 | G10: ALIA AKTAR | H10: =C10 -> 27 | I10: =IF(UPPER(H10)="AB","AB",ROUND(((H10/H$9)*100),0)) -> 68
A11: 2 | B11: ANUSHA V | C11: 10 | D11: =IF(UPPER(C11)="AB","AB",ROUND(((C11/C$9)*100),0)) -> 25 | F11: 2 | G11: ANUSHA V | H11: =C11 -> 10 | I11: =IF(UPPER(H11)="AB","AB",ROUND(((H11/H$9)*100),0)) -> 25
A12: 3 | B12: ANUSHREE BEHERA | C12: 17 | D12: =IF(UPPER(C12)="AB","AB",ROUND(((C12/C$9)*100),0)) -> 43 | F12: 3 | G12: ANUSHREE BEHERA | H12: =C12 -> 17 | I12: =IF(UPPER(H12)="AB","AB",ROUND(((H12/H$9)*100),0)) -> 43
A13: 4 | B13: ARNESHA DEBNATH | C13: 30 | D13: =IF(UPPER(C13)="AB","AB",ROUND(((C13/C$9)*100),0)) -> 75 | F13: 4 | G13: ARNESHA DEBNATH | H13: =C13 -> 30 | I13: =IF(UPPER(H13)="AB","AB",ROUND(((H13/H$9)*100),0)) -> 75
A14: 5 | B14: ARSALA KHATUN | C14: 24 | D14: =IF(UPPER(C14)="AB","AB",ROUND(((C14/C$9)*100),0)) -> 60 | F14: 5 | G14: ARSALA KHATUN | H14: =C14 -> 24 | I14: =IF(UPPER(H14)="AB","AB",ROUND(((H14/H$9)*100),0)) -> 60
A15: 6 | B15: BAISHALI DEBNATH | C15: 27 | D15: =IF(UPPER(C15)="AB","AB",ROUND(((C15/C$9)*100),0)) -> 68 | F15: 6 | G15: BAISHALI DEBNATH | H15: =C15 -> 27 | I15: =IF(UPPER(H15)="AB","AB",ROUND(((H15/H$9)*100),0)) -> 68
A16: 7 | B16: BIPASHA DEBNATH | C16: 35 | D16: =IF(UPPER(C16)="AB","AB",ROUND(((C16/C$9)*100),0)) -> 88 | F16: 7 | G16: BIPASHA DEBNATH | H16: =C16 -> 35 | I16: =IF(UPPER(H16)="AB","AB",ROUND(((H16/H$9)*100),0)) -> 88
A17: 8 | B17: CHANDRA DAS | C17: 6 | D17: =IF(UPPER(C17)="AB","AB",ROUND(((C17/C$9)*100),0)) -> 15 | F17: 8 | G17: CHANDRA DAS | H17: =C17 -> 6 | I17: =IF(UPPER(H17)="AB","AB",ROUND(((H17/H$9)*100),0)) -> 15
A18: 9 | B18: JENISHA DEBBARMA | C18: 24 | D18: =IF(UPPER(C18)="AB","AB",ROUND(((C18/C$9)*100),0)) -> 60 | F18: 9 | G18: JENISHA DEBBARMA | H18: =C18 -> 24 | I18: =IF(UPPER(H18)="AB","AB",ROUND(((H18/H$9)*100),0)) -> 60
A19: 10 | B19: JIYA DEBBARMA | C19: 9 | D19: =IF(UPPER(C19)="AB","AB",ROUND(((C19/C$9)*100),0)) -> 23 | F19: 10 | G19: JIYA DEBBARMA | H19: =C19 -> 9 | I19: =IF(UPPER(H19)="AB","AB",ROUND(((H19/H$9)*100),0)) -> 23
A20: 11 | B20: JOYDIPA DAS | C20: 11 | D20: =IF(UPPER(C20)="AB","AB",ROUND(((C20/C$9)*100),0)) -> 28 | F20: 11 | G20: JOYDIPA DAS | H20: =C20 -> 11 | I20: =IF(UPPER(H20)="AB","AB",ROUND(((H20/H$9)*100),0)) -> 28
A21: 12 | B21: MAITRI MAJUMDER | C21: 11 | D21: =IF(UPPER(C21)="AB","AB",ROUND(((C21/C$9)*100),0)) -> 28 | F21: 12 | G21: MAITRI MAJUMDER | H21: =C21 -> 11 | I21: =IF(UPPER(H21)="AB","AB",ROUND(((H21/H$9)*100),0)) -> 28
... A40: 31 | B40: NVK VARA PRASAD | C40: 27 | D40: =IF(UPPER(C40)="AB","AB",ROUND(((C40/C$9)*100),0)) -> 68 | F40: 31 | G40: NVK VARA PRASAD | H40: =C40 -> 27 | I40: =IF(UPPER(H40)="AB","AB",ROUND(((H40/H$9)*100),0)) -> 68
A41: 32 | B41: OMKAR DEBNATH | C41: AB | D41: =IF(UPPER(C41)="AB","AB",ROUND(((C41/C$9)*100),0)) -> AB | F41: 32 | G41: OMKAR DEBNATH | H41: =C41 -> AB | I41: =IF(UPPER(H41)="AB","AB",ROUND(((H41/H$9)*100),0)) -> AB
A42: 33 | B42: PRITHI RAJ BHOWMIK | C42: 16 | D42: =IF(UPPER(C42)="AB","AB",ROUND(((C42/C$9)*100),0)) -> 40 | F42: 33 | G42: PRITHI RAJ BHOWMIK | H42: =C42 -> 16 | I42: =IF(UPPER(H42)="AB","AB",ROUND(((H42/H$9)*100),0)) -> 40
A43: 34 | B43: RIK DEBNATH | C43: 25 | D43: =IF(UPPER(C43)="AB","AB",ROUND(((C43/C$9)*100),0)) -> 63 | F43: 34 | G43: RIK DEBNATH | H43: =C43 -> 25 | I43: =IF(UPPER(H43)="AB","AB",ROUND(((H43/H$9)*100),0)) -> 63
A44: 35 | B44: ROHITH KRISHNA R | C44: 16 | D44: =IF(UPPER(C44)="AB","AB",ROUND(((C44/C$9)*100),0)) -> 40 | F44: 35 | G44: ROHITH KRISHNA R | H44: =C44 -> 16 | I44: =IF(UPPER(H44)="AB","AB",ROUND(((H44/H$9)*100),0)) -> 40
A45: 36 | B45: ROHIT KUMAR | C45: 23 | D45: =IF(UPPER(C45)="AB","AB",ROUND(((C45/C$9)*100),0)) -> 58 | F45: 36 | G45: ROHIT KUMAR | H45: =C45 -> 23 | I45: =IF(UPPER(H45)="AB","AB",ROUND(((H45/H$9)*100),0)) -> 58
A46: 37 | B46: SAURAV SINHA | C46: 26 | D46: =IF(UPPER(C46)="AB","AB",ROUND(((C46/C$9)*100),0)) -> 65 | F46: 37 | G46: SAURAV SINHA | H46: =C46 -> 26 | I46: =IF(UPPER(H46)="AB","AB",ROUND(((H46/H$9)*100),0)) -> 65
A47: 38 | B47: SHANTANU DAS | C47: 11 | D47: =IF(UPPER(C47)="AB","AB",ROUND(((C47/C$9)*100),0)) -> 28 | F47: 38 | G47: SHANTANU DAS | H47: =C47 -> 11 | I47: =IF(UPPER(H47)="AB","AB",ROUND(((H47/H$9)*100),0)) -> 28
A48: 39 | B48: SHARTHAKI RUDRA PAUL | C48: 24 | D48: =IF(UPPER(C48)="AB","AB",ROUND(((C48/C$9)*100),0)) -> 60 | F48: 39 | G48: SHARTHAKI RUDRA PAUL | H48: =C48 -> 24 | I48: =IF(UPPER(H48)="AB","AB",ROUND(((H48/H$9)*100),0)) -> 60
A49: 40 | B49: SOMYANSHU SAHOO | C49: 17 | D49: =IF(UPPER(C49)="AB","AB",ROUND(((C49/C$9)*100),0)) -> 43 | F49: 40 | G49: SOMYANSHU SAHOO | H49: =C49 -> 17 | I49: =IF(UPPER(H49)="AB","AB",ROUND(((H49/H$9)*100),0)) -> 43
A50: 41 | B50: SUDIP ROY | C50: 20 | D50: =IF(UPPER(C50)="AB","AB",ROUND(((C50/C$9)*100),0)) -> 50 | F50: 41 | G50: SUDIP ROY | H50: =C50 -> 20 | I50: =IF(UPPER(H50)="AB","AB",ROUND(((H50/H$9)*100),0)) -> 50
A51: 42 | B51: SUMANTA DEBBARMA | C51: 12 | D51: =IF(UPPER(C51)="AB","AB",ROUND(((C51/C$9)*100),0)) -> 30 | F51: 42 | G51: SUMANTA DEBBARMA | H51: =C51 -> 12 | I51: =IF(UPPER(H51)="AB","AB",ROUND(((H51/H$9)*100),0)) -> 30
D58: *AB-Absent | I58: *AB-Absent
A59: % Marks [Result Analysis] | F59: % Marks [Result Analysis]
A60: 90=< | B60: =COUNTIF(D10:D57,">=90") -> 3 | C60: Appered | D60: =COUNT(H10:H57) -> 41 | F60: 90=< | G60: =COUNTIF(I10:I57,">=90") -> 3 | H60: Appered | I60: =COUNT(H10:H57) -> 41
A61: 75-89.9 | B61: =COUNTIF(D10:D57,">=75")-B60 -> 3 | C61: Absent | D61: =COUNTIF(D10:D57,"=AB") -> 1 | F61: 75-89.9 | G61: =COUNTIF(I10:I57,">=75")-G60 -> 3 | H61: Absent | I61: =COUNTIF(I10:I57,"=AB") -> 1
A62: 60-74.9 | B62: =COUNTIF(D10:D57,">=60")-B61-B60 -> 11 | C62: Passed | D62: =COUNTIF(D10:D57,">=33") -> 28 | F62: 60-74.9 | G62: =COUNTIF(I10:I57,">=60")-G61-G60 -> 11 | H62: Passed | I62: =COUNTIF(I10:I57,">=33") -> 28
A63: 45-59.9 | B63: =COUNTIF(D10:D57,">=45")-B62-B61-B60 -> 5 | C63: Pass % | D63: =(D62/D60)*100 -> 68.292683 | F63: 45-59.9 | G63: =COUNTIF(I10:I57,">=45")-G62-G61-G60 -> 5 | H63: Pass % | I63: =(I62/I60)*100 -> 68.292683
A64: 33-44.9 | B64: =COUNTIF(D10:D57,">=33")-B63-B62-B61-B60 -> 6 | F64: 33-44.9 | G64: =COUNTIF(I10:I57,">=33")-G63-G62-G61-G60 -> 6
...

Sheet Maths
A1: KENDRIYA VIDYALAYA NIT AGARTALA | F1: KENDRIYA VIDYALAYA NIT AGARTALA
A2: SESSION : 2025-26 | F2: SESSION : 2025-26
B3: MARK-STATEMENT | D3: PT 2 | G3: MARK-STATEMENT | I3: PT 2
A4: Class : VI | F4: Class : VI
A5: Subject: MATHS | B5: Mathematics | F5: Subject: MATHS
A6: No. of Ans. Book : 41 | F6: No. of Ans. Book : 41
A7: Name of Examiner : Ms Nitu Sinha | F7: Name of Examiner : Ms Nitu Sinha
A8: Roll | B8: Name | C8: Marks | D8: % Marks | F8: Roll | G8: Name | H8: Marks | I8: % Marks
C9: 40 | H9: 40
A10: 1 | B10: ALIA AKTAR | C10: 15 | D10: =IF(UPPER(C10)="AB","AB",ROUND(((C10/C$9)*100),0)) -> 38 | F10: 1 | G10: ALIA AKTAR | H10: =C10 -> 15 | I10: =IF(UPPER(H10)="AB","AB",ROUND(((H10/H$9)*100),0)) -> 38
A11: 2 | B11: ANUSHA V | C11: 10 | D11: =IF(UPPER(C11)="AB","AB",ROUND(((C11/C$9)*100),0)) -> 25 | F11: 2 | G11: ANUSHA V | H11: =C11 -> 10 | I11: =IF(UPPER(H11)="AB","AB",ROUND(((H11/H$9)*100),0)) -> 25
A12: 3 | B12: ANUSHREE BEHERA | C12: 28 | D12: =IF(UPPER(C12)="AB","AB",ROUND(((C12/C$9)*100),0)) -> 70 | F12: 3 | G12: ANUSHREE BEHERA | H12: =C12 -> 28 | I12: =IF(UPPER(H12)="AB","AB",ROUND(((H12/H$9)*100),0)) -> 70
A13: 4 | B13: ARNESHA DEBNATH | C13: 29 | D13: =IF(UPPER(C13)="AB","AB",ROUND(((C13/C$9)*100),0)) -> 73 | F13: 4 | G13: ARNESHA DEBNATH | H13: =C13 -> 29 | I13: =IF(UPPER(H13)="AB","AB",ROUND(((H13/H$9)*100),0)) -> 73
A14: 5 | B14: ARSALA KHATUN | C14: 20 | D14: =IF(UPPER(C14)="AB","AB",ROUND(((C14/C$9)*100),0)) -> 50 | F14: 5 | G14: ARSALA KHATUN | H14: =C14 -> 20 | I14: =IF(UPPER(H14)="AB","AB",ROUND(((H14/H$9)*100),0)) -> 50
A15: 6 | B15: BAISHALI DEBNATH | C15: 30 | D15: =IF(UPPER(C15)="AB","AB",ROUND(((C15/C$9)*100),0)) -> 75 | F15: 6 | G15: BAISHALI DEBNATH | H15: =C15 -> 30 | I15: =IF(UPPER(H15)="AB","AB",ROUND(((H15/H$9)*100),0)) -> 75
A16: 7 | B16: BIPASHA DEBNATH | C16: 30 | D16: =IF(UPPER(C16)="AB","AB",ROUND(((C16/C$9)*100),0)) -> 75 | F16: 7 | G16: BIPASHA DEBNATH | H16: =C16 -> 30 | I16: =IF(UPPER(H16)="AB","AB",ROUND(((H16/H$9)*100),0)) -> 75
A17: 8 | B17: CHANDRA DAS | C17: 5 | D17: =IF(UPPER(C17)="AB","AB",ROUND(((C17/C$9)*100),0)) -> 13 | F17: 8 | G17: CHANDRA DAS | H17: =C17 -> 5 | I17: =IF(UPPER(H17)="AB","AB",ROUND(((H17/H$9)*100),0)) -> 13
A18: 9 | B18: JENISHA DEBBARMA | C18: 10 | D18: =IF(UPPER(C18)="AB","AB",ROUND(((C18/C$9)*100),0)) -> 25 | F18: 9 | G18: JENISHA DEBBARMA | H18: =C18 -> 10 | I18: =IF(UPPER(H18)="AB","AB",ROUND(((H18/H$9)*100),0)) -> 25
A19: 10 | B19: JIYA DEBBARMA | C19: 3 | D19: =IF(UPPER(C19)="AB","AB",ROUND(((C19/C$9)*100),0)) -> 8 | F19: 10 | G19: JIYA DEBBARMA | H19: =C19 -> 3 | I19: =IF(UPPER(H19)="AB","AB",ROUND(((H19/H$9)*100),0)) -> 8
A20: 11 | B20: JOYDIPA DAS | C20: 9 | D20: =IF(UPPER(C20)="AB","AB",ROUND(((C20/C$9)*100),0)) -> 23 | F20: 11 | G20: JOYDIPA DAS | H20: =C20 -> 9 | I20: =IF(UPPER(H20)="AB","AB",ROUND(((H20/H$9)*100),0)) -> 23
A21: 12 | B21: MAITRI MAJUMDER | C21: 14 | D21: =IF(UPPER(C21)="AB","AB",ROUND(((C21/C$9)*100),0)) -> 35 | F21: 12 | G21: MAITRI MAJUMDER | H21: =C21 -> 14 | I21: =IF(UPPER(H21)="AB","AB",ROUND(((H21/H$9)*100),0)) -> 35
... A46: 37 | B46: SAURAV SINHA | C46: 12 | D46: =IF(UPPER(C46)="AB","AB",ROUND(((C46/C$9)*100),0)) -> 30 | F46: 37 | G46: SAURAV SINHA | H46: =C46 -> 12 | I46: =IF(UPPER(H46)="AB","AB",ROUND(((H46/H$9)*100),0)) -> 30
A47: 38 | B47: SHANTANU DAS | C47: AB | D47: =IF(UPPER(C47)="AB","AB",ROUND(((C47/C$9)*100),0)) -> AB | F47: 38 | G47: SHANTANU DAS | H47: =C47 -> AB | I47: =IF(UPPER(H47)="AB","AB",ROUND(((H47/H$9)*100),0)) -> AB
A48: 39 | B48: SHARTHAKI RUDRA PAUL | C48: 36 | D48: =IF(UPPER(C48)="AB","AB",ROUND(((C48/C$9)*100),0)) -> 90 | F48: 39 | G48: SHARTHAKI RUDRA PAUL | H48: =C48 -> 36 | I48: =IF(UPPER(H48)="AB","AB",ROUND(((H48/H$9)*100),0)) -> 90
A49: 40 | B49: SOMYANSHU SAHOO | C49: 24 | D49: =IF(UPPER(C49)="AB","AB",ROUND(((C49/C$9)*100),0)) -> 60 | F49: 40 | G49: SOMYANSHU SAHOO | H49: =C49 -> 24 | I49: =IF(UPPER(H49)="AB","AB",ROUND(((H49/H$9)*100),0)) -> 60
A50: 41 | B50: SUDIP ROY | C50: 28 | D50: =IF(UPPER(C50)="AB","AB",ROUND(((C50/C$9)*100),0)) -> 70 | F50: 41 | G50: SUDIP ROY | H50: =C50 -> 28 | I50: =IF(UPPER(H50)="AB","AB",ROUND(((H50/H$9)*100),0)) -> 70
A51: 42 | B51: SUMANTA DEBBARMA | C51: 11 | D51: =IF(UPPER(C51)="AB","AB",ROUND(((C51/C$9)*100),0)) -> 28 | F51: 42 | G51: SUMANTA DEBBARMA | H51: =C51 -> 11 | I51: =IF(UPPER(H51)="AB","AB",ROUND(((H51/H$9)*100),0)) -> 28
D58: *AB-Absent | I58: *AB-Absent
A59: % Marks [Result Analysis] | F59: % Marks [Result Analysis]
A60: 90=< | B60: =COUNTIF(D10:D57,">=90") -> 4 | C60: Appered | D60: =COUNT(C10:C57) -> 41 | F60: 90=< | G60: =COUNTIF(I10:I57,">=90") -> 4 | H60: Appered | I60: =COUNT(H10:H57) -> 41
A61: 75-89.9 | B61: =COUNTIF(D10:D57,">=75")-B60 -> 5 | C61: Absent | D61: =COUNTIF(D10:D57,"=AB") -> 1 | F61: 75-89.9 | G61: =COUNTIF(I10:I57,">=75")-G60 -> 5 | H61: Absent | I61: =COUNTIF(I10:I57,"=AB") -> 1
A62: 60-74.9 | B62: =COUNTIF(D10:D57,">=60")-B61-B60 -> 7 | C62: Passed | D62: =COUNTIF(D10:D57,">=33") -> 27 | F62: 60-74.9 | G62: =COUNTIF(I10:I57,">=60")-G61-G60 -> 7 | H62: Passed | I62: =COUNTIF(I10:I57,">=33") -> 27
A63: 45-59.9 | B63: =COUNTIF(D10:D57,">=45")-B62-B61-B60 -> 4 | C63: Pass % | D63: =(D62/D60)*100 -> 65.853659 | F63: 45-59.9 | G63: =COUNTIF(I10:I57,">=45")-G62-G61-G60 -> 4 | H63: Pass % | I63: =(I62/I60)*100 -> 65.853659
A64: 33-44.9 | B64: =COUNTIF(D10:D57,">=33")-B63-B62-B61-B60 -> 7 | F64: 33-44.9 | G64: =COUNTIF(I10:I57,">=33")-G63-G62-G61-G60 -> 7
A65: <33 | B65: =COUNTIF(D10:D57,"<33")-COUNTIF(D10:D57,"=0.0") -> 14 | F65: <33 | G65: =COUNTIF(I10:I57,"<33")-COUNTIF(I10:I57,"=0.0") -> 14
A67: Sign. of Examiner_________________ | F67: Sign. of Examiner_________________
A68: Sign. of Checker_________________ | D68: Principal | F68: Sign. of Checker_________________ | I68: Principal

Sheet Science
A1: KENDRIYA VIDYALAYA NIT AGARTALA | F1: KENDRIYA VIDYALAYA NIT AGARTALA
A2: SESSION : 2025-26 | F2: SESSION : 2025-26
B3: MARK-STATEMENT | D3: PT 2 | G3: MARK-STATEMENT | I3: PT 2
A4: Class : VI | F4: Class : VI
A5: Subject: SCIENCE | F5: Subject: SCIENCE
A6: No. of Ans. Book : 42 | F6: No. of Ans. Book : 42
A7: Name of Examiner : Ms Jesmin Sinha | F7: Name of Examiner : Ms Jesmin Sinha
A8: Roll | B8: Name | C8: Marks | D8: % Marks | F8: Roll | G8: Name | H8: Marks | I8: % Marks
C9: 40 | H9: 40
A10: 1 | B10: ALIA AKTAR | C10: 20 | D10: =IF(UPPER(C10)="AB","AB",ROUND(((C10/C$9)*100),0)) -> 50 | F10: 1 | G10: ALIA AKTAR | H10: =C10 -> 20 | I10: =IF(UPPER(H10)="AB","AB",ROUND(((H10/H$9)*100),0)) -> 50
A11: 2 | B11: ANUSHA V | C11: 9 | D11: =IF(UPPER(C11)="AB","AB",ROUND(((C11/C$9)*100),0)) -> 23 | F11: 2 | G11: ANUSHA V | H11: =C11 -> 9 | I11: =IF(UPPER(H11)="AB","AB",ROUND(((H11/H$9)*100),0)) -> 23
A12: 3 | B12: ANUSHREE BEHERA | C12: 24 | D12: =IF(UPPER(C12)="AB","AB",ROUND(((C12/C$9)*100),0)) -> 60 | F12: 3 | G12: ANUSHREE BEHERA | H12: =C12 -> 24 | I12: =IF(UPPER(H12)="AB","AB",ROUND(((H12/H$9)*100),0)) -> 60
A13: 4 | B13: ARNESHA DEBNATH | C13: 30 | D13: =IF(UPPER(C13)="AB","AB",ROUND(((C13/C$9)*100),0)) -> 75 | F13: 4 | G13: ARNESHA DEBNATH | H13: =C13 -> 30 | I13: =IF(UPPER(H13)="AB","AB",ROUND(((H13/H$9)*100),0)) -> 75
A14: 5 | B14: ARSALA KHATUN | C14: 20 | D14: =IF(UPPER(C14)="AB","AB",ROUND(((C14/C$9)*100),0)) -> 50 | F14: 5 | G14: ARSALA KHATUN | H14: =C14 -> 20 | I14: =IF(UPPER(H14)="AB","AB",ROUND(((H14/H$9)*100),0)) -> 50
A15: 6 | B15: BAISHALI DEBNATH | C15: 26 | D15: =IF(UPPER(C15)="AB","AB",ROUND(((C15/C$9)*100),0)) -> 65 | F15: 6 | G15: BAISHALI DEBNATH | H15: =C15 -> 26 | I15: =IF(UPPER(H15)="AB","AB",ROUND(((H15/H$9)*100),0)) -> 65
A16: 7 | B16: BIPASHA DEBNATH | C16: 35 | D16: =IF(UPPER(C16)="AB","AB",ROUND(((C16/C$9)*100),0)) -> 88 | F16: 7 | G16: BIPASHA DEBNATH | H16: =C16 -> 35 | I16: =IF(UPPER(H16)="AB","AB",ROUND(((H16/H$9)*100),0)) -> 88
A17: 8 | B17: CHANDRA DAS | C17: 2 | D17: =IF(UPPER(C17)="AB","AB",ROUND(((C17/C$9)*100),0)) -> 5 | F17: 8 | G17: CHANDRA DAS | H17: =C17 -> 2 | I17: =IF(UPPER(H17)="AB","AB",ROUND(((H17/H$9)*100),0)) -> 5
A18: 9 | B18: JENISHA DEBBARMA | C18: 9 | D18: =IF(UPPER(C18)="AB","AB",ROUND(((C18/C$9)*100),0)) -> 23 | F18: 9 | G18: JENISHA DEBBARMA | H18: =C18 -> 9 | I18: =IF(UPPER(H18)="AB","AB",ROUND(((H18/H$9)*100),0)) -> 23
A19: 10 | B19: JIYA DEBBARMA | C19: 4 | D19: =IF(UPPER(C19)="AB","AB",ROUND(((C19/C$9)*100),0)) -> 10 | F19: 10 | G19: JIYA DEBBARMA | H19: =C19 -> 4 | I19: =IF(UPPER(H19)="AB","AB",ROUND(((H19/H$9)*100),0)) -> 10
A20: 11 | B20: JOYDIPA DAS | C20: 6 | D20: =IF(UPPER(C20)="AB","AB",ROUND(((C20/C$9)*100),0)) -> 15 | F20: 11 | G20: JOYDIPA DAS | H20: =C20 -> 6 | I20: =IF(UPPER(H20)="AB","AB",ROUND(((H20/H$9)*100),0)) -> 15
A21: 12 | B21: MAITRI MAJUMDER | C21: 8 | D21: =IF(UPPER(C21)="AB","AB",ROUND(((C21/C$9)*100),0)) -> 20 | F21: 12 | G21: MAITRI MAJUMDER | H21: =C21 -> 8 | I21: =IF(UPPER(H21)="AB","AB",ROUND(((H21/H$9)*100),0)) -> 20
... A51: 42 | B51: SUMANTA DEBBARMA | C51: 8 | D51: =IF(UPPER(C51)="AB","AB",ROUND(((C51/C$9)*100),0)) -> 20 | F51: 42 | G51: SUMANTA DEBBARMA | H51: =C51 -> 8 | I51: =IF(UPPER(H51)="AB","AB",ROUND(((H51/H$9)*100),0)) -> 20
D58: *AB-Absent | I58: *AB-Absent
A59: % Marks [Result Analysis] | F59: % Marks [Result Analysis]
A60: 90=< | B60: =COUNTIF(D10:D57,">=90") -> 2 | C60: Appered | D60: =COUNT(C10:C57) -> 42 | F60: 90=< | G60: =COUNTIF(I10:I57,">=90") -> 2 | H60: Appered | I60: =COUNT(H10:H57) -> 42
A61: 75-89.9 | B61: =COUNTIF(D10:D57,">=75")-B60 -> 3 | C61: Absent | D61: =COUNTIF(D10:D57,"=AB") -> 0 | F61: 75-89.9 | G61: =COUNTIF(I10:I57,">=75")-G60 -> 3 | H61: Absent | I61: =COUNTIF(I10:I57,"=AB") -> 0
A62: 60-74.9 | B62: =COUNTIF(D10:D57,">=60")-B61-B60 -> 6 | C62: Passed | D62: =COUNTIF(D10:D57,">=33") -> 27 | F62: 60-74.9 | G62: =COUNTIF(I10:I57,">=60")-G61-G60 -> 6 | H62: Passed | I62: =COUNTIF(I10:I57,">=33") -> 27
A63: 45-59.9 | B63: =COUNTIF(D10:D57,">=45")-B62-B61-B60 -> 8 | C63: Pass % | D63: =(D62/D60)*100 -> 64.285714 | F63: 45-59.9 | G63: =COUNTIF(I10:I57,">=45")-G62-G61-G60 -> 8 | H63: Pass % | I63: =(I62/I60)*100 -> 64.285714
A64: 33-44.9 | B64: =COUNTIF(D10:D57,">=33")-B63-B62-B61-B60 -> 8 | F64: 33-44.9 | G64: =COUNTIF(I10:I57,">=33")-G63-G62-G61-G60 -> 8
A65: <33 | B65: =COUNTIF(D10:D57,"<33")-COUNTIF(D10:D57,"=0.0") -> 15 | F65: <33 | G65: =COUNTIF(I10:I57,"<33")-COUNTIF(I10:I57,"=0.0") -> 15
A67: Sign. of Examiner_________________ | F67: Sign. of Examiner_________________
A68: Sign. of Checker_________________ | D68: Principal | F68: Sign. of Checker_________________ | I68: Principal

Sheet S.St.
A1: KENDRIYA VIDYALAYA NIT AGARTALA | F1: KENDRIYA VIDYALAYA NIT AGARTALA
A2: SESSION : 2025-26 | F2: SESSION : 2025-26
B3: MARK-STATEMENT | D3: PT 2 | G3: MARK-STATEMENT | I3: PT 2
A4: Class : VI | F4: Class : VI
A5: Subject: SOCIAL SCIENCE | F5: Subject: SOCIAL SCIENCE
A6: No. of Ans. Book : 41 | F6: No. of Ans. Book : 41
A7: Name of Examiner : Mr Rajesh Singh | F7: Name of Examiner : Mr Rajesh Singh
A8: Roll | B8: Name | C8: Marks | D8: % Marks | F8: Roll | G8: Name | H8: Marks | I8: % Marks
C9: 40 | H9: 40
A10: 1 | B10: ALIA AKTAR | C10: 14 | D10: =IF(UPPER(C10)="AB","AB",ROUND(((C10/C$9)*100),0)) -> 35 | F10: 1 | G10: ALIA AKTAR | H10: =C10 -> 14 | I10: =IF(UPPER(H10)="AB","AB",ROUND(((H10/H$9)*100),0)) -> 35
A11: 2 | B11: ANUSHA V | C11: 6 | D11: =IF(UPPER(C11)="AB","AB",ROUND(((C11/C$9)*100),0)) -> 15 | F11: 2 | G11: ANUSHA V | H11: =C11 -> 6 | I11: =IF(UPPER(H11)="AB","AB",ROUND(((H11/H$9)*100),0)) -> 15
A12: 3 | B12: ANUSHREE BEHERA | C12: 25 | D12: =IF(UPPER(C12)="AB","AB",ROUND(((C12/C$9)*100),0)) -> 63 | F12: 3 | G12: ANUSHREE BEHERA | H12: =C12 -> 25 | I12: =IF(UPPER(H12)="AB","AB",ROUND(((H12/H$9)*100),0)) -> 63
A13: 4 | B13: ARNESHA DEBNATH | C13: 25 | D13: =IF(UPPER(C13)="AB","AB",ROUND(((C13/C$9)*100),0)) -> 63 | F13: 4 | G13: ARNESHA DEBNATH | H13: =C13 -> 25 | I13: =IF(UPPER(H13)="AB","AB",ROUND(((H13/H$9)*100),0)) -> 63
A14: 5 | B14: ARSALA KHATUN | C14: 16 | D14: =IF(UPPER(C14)="AB","AB",ROUND(((C14/C$9)*100),0)) -> 40 | F14: 5 | G14: ARSALA KHATUN | H14: =C14 -> 16 | I14: =IF(UPPER(H14)="AB","AB",ROUND(((H14/H$9)*100),0)) -> 40
A15: 6 | B15: BAISHALI DEBNATH | C15: 19 | D15: =IF(UPPER(C15)="AB","AB",ROUND(((C15/C$9)*100),0)) -> 48 | F15: 6 | G15: BAISHALI DEBNATH | H15: =C15 -> 19 | I15: =IF(UPPER(H15)="AB","AB",ROUND(((H15/H$9)*100),0)) -> 48
A16: 7 | B16: BIPASHA DEBNATH | C16: 31 | D16: =IF(UPPER(C16)="AB","AB",ROUND(((C16/C$9)*100),0)) -> 78 | F16: 7 | G16: BIPASHA DEBNATH | H16: =C16 -> 31 | I16: =IF(UPPER(H16)="AB","AB",ROUND(((H16/H$9)*100),0)) -> 78
A17: 8 | B17: CHANDRA DAS | C17: 4 | D17: =IF(UPPER(C17)="AB","AB",ROUND(((C17/C$9)*100),0)) -> 10 | F17: 8 | G17: CHANDRA DAS | H17: =C17 -> 4 | I17: =IF(UPPER(H17)="AB","AB",ROUND(((H17/H$9)*100),0)) -> 10
A18: 9 | B18: JENISHA DEBBARMA | C18: 10 | D18: =IF(UPPER(C18)="AB","AB",ROUND(((C18/C$9)*100),0)) -> 25 | F18: 9 | G18: JENISHA DEBBARMA | H18: =C18 -> 10 | I18: =IF(UPPER(H18)="AB","AB",ROUND(((H18/H$9)*100),0)) -> 25
A19: 10 | B19: JIYA DEBBARMA | C19: 4 | D19: =IF(UPPER(C19)="AB","AB",ROUND(((C19/C$9)*100),0)) -> 10 | F19: 10 | G19: JIYA DEBBARMA | H19: =C19 -> 4 | I19: =IF(UPPER(H19)="AB","AB",ROUND(((H19/H$9)*100),0)) -> 10
A20: 11 | B20: JOYDIPA DAS | C20: 7 | D20: =IF(UPPER(C20)="AB","AB",ROUND(((C20/C$9)*100),0)) -> 18 | F20: 11 | G20: JOYDIPA DAS | H20: =C20 -> 7 | I20: =IF(UPPER(H20)="AB","AB",ROUND(((H20/H$9)*100),0)) -> 18
A21: 12 | B21: MAITRI MAJUMDER | C21: 11 | D21: =IF(UPPER(C21)="AB","AB",ROUND(((C21/C$9)*100),0)) -> 28 | F21: 12 | G21: MAITRI MAJUMDER | H21: =C21 -> 11 | I21: =IF(UPPER(H21)="AB","AB",ROUND(((H21/H$9)*100),0)) -> 28
... A51: 42 | B51: SUMANTA DEBBARMA | C51: 16 | D51: =IF(UPPER(C51)="AB","AB",ROUND(((C51/C$9)*100),0)) -> 40 | F51: 42 | G51: SUMANTA DEBBARMA | H51: =C51 -> 16 | I51: =IF(UPPER(H51)="AB","AB",ROUND(((H51/H$9)*100),0)) -> 40
D58: *AB-Absent | I58: *AB-Absent
A59: % Marks [Result Analysis] | F59: % Marks [Result Analysis]
A60: 90=< | B60: =COUNTIF(D10:D57,">=90") -> 3 | C60: Appered | D60: =COUNT(C10:C57) -> 42 | F60: 90=< | G60: =COUNTIF(I10:I57,">=90") -> 3 | H60: Appered | I60: =COUNT(H10:H57) -> 42
A61: 75-89.9 | B61: =COUNTIF(D10:D57,">=75")-B60 -> 3 | C61: Absent | D61: =COUNTIF(D10:D57,"=AB") -> 0 | F61: 75-89.9 | G61: =COUNTIF(I10:I57,">=75")-G60 -> 3 | H61: Absent | I61: =COUNTIF(I10:I57,"=AB") -> 0
A62: 60-74.9 | B62: =COUNTIF(D10:D57,">=60")-B61-B60 -> 7 | C62: Passed | D62: =COUNTIF(D10:D57,">=33") -> 27 | F62: 60-74.9 | G62: =COUNTIF(I10:I57,">=60")-G61-G60 -> 7 | H62: Passed | I62: =COUNTIF(I10:I57,">=33") -> 27
A63: 45-59.9 | B63: =COUNTIF(D10:D57,">=45")-B62-B61-B60 -> 7 | C63: Pass % | D63: =(D62/D60)*100 -> 64.285714 | F63: 45-59.9 | G63: =COUNTIF(I10:I57,">=45")-G62-G61-G60 -> 7 | H63: Pass % | I63: =(I62/I60)*100 -> 64.285714
A64: 33-44.9 | B64: =COUNTIF(D10:D57,">=33")-B63-B62-B61-B60 -> 7 | F64: 33-44.9 | G64: =COUNTIF(I10:I57,">=33")-G63-G62-G61-G60 -> 7
A65: <33 | B65: =COUNTIF(D10:D57,"<33")-COUNTIF(D10:D57,"=0.0") -> 15 | F65: <33 | G65: =COUNTIF(I10:I57,"<33")-COUNTIF(I10:I57,"=0.0") -> 15
A67: Sign. of Examiner_________________ | F67: Sign. of Examiner_________________
A68: Sign. of Checker_________________ | D68: Principal | F68: Sign. of Checker_________________ | I68: Principal

Sheet संस्कृत
A1: KENDRIYA VIDYALAYA NIT AGARTALA | F1: KENDRIYA VIDYALAYA NIT AGARTALA
A2: SESSION : 2025-26 | F2: SESSION : 2025-26
B3: MARK-STATEMENT | D3: PT 2 | G3: MARK-STATEMENT | I3: PT 2
A4: Class : VI | F4: Class : VI
A5: Subject: Sanskrit | F5: Subject: Sanskrit
A6: No. of Ans. Book : 41 | F6: No. of Ans. Book : 41
A7: Name of Examiner : Ms Susmita Dey | F7: Name of Examiner : Ms Susmita Dey
A8: Roll | B8: Name | C8: Marks | D8: % Marks | F8: Roll | G8: Name | H8: Marks | I8: % Marks
C9: 40 | H9: 40
A10: 1 | B10: ALIA AKTAR | C10: 23 | D10: =IF(UPPER(C10)="AB","AB",ROUND(((C10/C$9)*100),0)) -> 58 | F10: 1 | G10: ALIA AKTAR | H10: =C10 -> 23 | I10: =IF(UPPER(H10)="AB","AB",ROUND(((H10/H$9)*100),0)) -> 58
A11: 2 | B11: ANUSHA V | C11: 20 | D11: =IF(UPPER(C11)="AB","AB",ROUND(((C11/C$9)*100),0)) -> 50 | F11: 2 | G11: ANUSHA V | H11: =C11 -> 20 | I11: =IF(UPPER(H11)="AB","AB",ROUND(((H11/H$9)*100),0)) -> 50
A12: 3 | B12: ANUSHREE BEHERA | C12: 32 | D12: =IF(UPPER(C12)="AB","AB",ROUND(((C12/C$9)*100),0)) -> 80 | F12: 3 | G12: ANUSHREE BEHERA | H12: =C12 -> 32 | I12: =IF(UPPER(H12)="AB","AB",ROUND(((H12/H$9)*100),0)) -> 80
A13: 4 | B13: ARNESHA DEBNATH | C13: 34 | D13: =IF(UPPER(C13)="AB","AB",ROUND(((C13/C$9)*100),0)) -> 85 | F13: 4 | G13: ARNESHA DEBNATH | H13: =C13 -> 34 | I13: =IF(UPPER(H13)="AB","AB",ROUND(((H13/H$9)*100),0)) -> 85
A14: 5 | B14: ARSALA KHATUN | C14: 29 | D14: =IF(UPPER(C14)="AB","AB",ROUND(((C14/C$9)*100),0)) -> 73 | F14: 5 | G14: ARSALA KHATUN | H14: =C14 -> 29 | I14: =IF(UPPER(H14)="AB","AB",ROUND(((H14/H$9)*100),0)) -> 73
A15: 6 | B15: BAISHALI DEBNATH | C15: 34 | D15: =IF(UPPER(C15)="AB","AB",ROUND(((C15/C$9)*100),0)) -> 85 | F15: 6 | G15: BAISHALI DEBNATH | H15: =C15 -> 34 | I15: =IF(UPPER(H15)="AB","AB",ROUND(((H15/H$9)*100),0)) -> 85
A16: 7 | B16: BIPASHA DEBNATH | C16: 40 | D16: =IF(UPPER(C16)="AB","AB",ROUND(((C16/C$9)*100),0)) -> 100 | F16: 7 | G16: BIPASHA DEBNATH | H16: =C16 -> 40 | I16: =IF(UPPER(H16)="AB","AB",ROUND(((H16/H$9)*100),0)) -> 100
A17: 8 | B17: CHANDRA DAS | C17: 13 | D17: =IF(UPPER(C17)="AB","AB",ROUND(((C17/C$9)*100),0)) -> 33 | F17: 8 | G17: CHANDRA DAS | H17: =C17 -> 13 | I17: =IF(UPPER(H17)="AB","AB",ROUND(((H17/H$9)*100),0)) -> 33
A18: 9 | B18: JENISHA DEBBARMA | C18: 25 | D18: =IF(UPPER(C18)="AB","AB",ROUND(((C18/C$9)*100),0)) -> 63 | F18: 9 | G18: JENISHA DEBBARMA | H18: =C18 -> 25 | I18: =IF(UPPER(H18)="AB","AB",ROUND(((H18/H$9)*100),0)) -> 63
A19: 10 | B19: JIYA DEBBARMA | C19: 19 | D19: =IF(UPPER(C19)="AB","AB",ROUND(((C19/C$9)*100),0)) -> 48 | F19: 10 | G19: JIYA DEBBARMA | H19: =C19 -> 19 | I19: =IF(UPPER(H19)="AB","AB",ROUND(((H19/H$9)*100),0)) -> 48
A20: 11 | B20: JOYDIPA DAS | C20: 27 | D20: =IF(UPPER(C20)="AB","AB",ROUND(((C20/C$9)*100),0)) -> 68 | F20: 11 | G20: JOYDIPA DAS | H20: =C20 -> 27 | I20: =IF(UPPER(H20)="AB","AB",ROUND(((H20/H$9)*100),0)) -> 68
A21: 12 | B21: MAITRI MAJUMDER | C21: 17 | D21: =IF(UPPER(C21)="AB","AB",ROUND(((C21/C$9)*100),0)) -> 43 | F21: 12 | G21: MAITRI MAJUMDER | H21: =C21 -> 17 | I21: =IF(UPPER(H21)="AB","AB",ROUND(((H21/H$9)*100),0)) -> 43
... A51: 42 | B51: SUMANTA DEBBARMA | C51: 20 | D51: =IF(UPPER(C51)="AB","AB",ROUND(((C51/C$9)*100),0)) -> 50 | F51: 42 | G51: SUMANTA DEBBARMA | H51: =C51 -> 20 | I51: =IF(UPPER(H51)="AB","AB",ROUND(((H51/H$9)*100),0)) -> 50
D58: *AB-Absent | I58: *AB-Absent
A59: % Marks [Result Analysis] | F59: % Marks [Result Analysis]
A60: 90=< | B60: =COUNTIF(D10:D57,">=90") -> 5 | C60: Appered | D60: =COUNT(C10:C57) -> 42 | F60: 90=< | G60: =COUNTIF(I10:I57,">=90") -> 5 | H60: Appered | I60: =COUNT(H10:H57) -> 42
A61: 75-89.9 | B61: =COUNTIF(D10:D57,">=75")-B60 -> 8 | C61: Absent | D61: =COUNTIF(D10:D57,"=AB") -> 0 | F61: 75-89.9 | G61: =COUNTIF(I10:I57,">=75")-G60 -> 8 | H61: Absent | I61: =COUNTIF(I10:I57,"=AB") -> 0
A62: 60-74.9 | B62: =COUNTIF(D10:D57,">=60")-B61-B60 -> 11 | C62: Passed | D62: =COUNTIF(D10:D57,">=33") -> 39 | F62: 60-74.9 | G62: =COUNTIF(I10:I57,">=60")-G61-G60 -> 11 | H62: Passed | I62: =COUNTIF(I10:I57,">=33") -> 39
A63: 45-59.9 | B63: =COUNTIF(D10:D57,">=45")-B62-B61-B60 -> 10 | C63: Pass % | D63: =(D62/D60)*100 -> 92.857143 | F63: 45-59.9 | G63: =COUNTIF(I10:I57,">=45")-G62-G61-G60 -> 10 | H63: Pass % | I63: =(I62/I60)*100 -> 92.857143
A64: 33-44.9 | B64: =COUNTIF(D10:D57,">=33")-B63-B62-B61-B60 -> 5 | F64: 33-44.9 | G64: =COUNTIF(I10:I57,">=33")-G63-G62-G61-G60 -> 5
A65: <33 | B65: =COUNTIF(D10:D57,"<33")-COUNTIF(D10:D57,"=0.0") -> 3 | F65: <33 | G65: =COUNTIF(I10:I57,"<33")-COUNTIF(I10:I57,"=0.0") -> 3
A67: Sign. of Examiner_________________ | F67: Sign. of Examiner_________________
A68: Sign. of Checker_________________ | D68: Principal | F68: Sign. of Checker_________________ | I68: Principal

Sheet AI
A1: KENDRIYA VIDYALAYA NIT AGARTALA | F1: KENDRIYA VIDYALAYA NIT AGARTALA
A2: SESSION : 2025-26 | F2: SESSION : 2025-26
B3: MARK-STATEMENT | D3: PT 2 | G3: MARK-STATEMENT | I3: PT 2
A4: Class : VI | F4: Class : VI
A5: Subject: AI | F5: Subject: AI
A6: No. of Ans. Book : 42 | F6: No. of Ans. Book : 42
A7: Name of Examiner : Ms Smita Debnath | F7: Name of Examiner : Ms Smita Debnath
A8: Roll | B8: Name | C8: Marks | D8: % Marks | F8: Roll | G8: Name | H8: Marks | I8: % Marks
C9: 40 | H9: 40
A10: 1 | B10: ALIA AKTAR | C10: 28 | D10: =IF(UPPER(C10)="AB","AB",ROUND(((C10/C$9)*100),0)) -> 70 | F10: 1 | G10: ALIA AKTAR | H10: =C10 -> 28 | I10: =IF(UPPER(H10)="AB","AB",ROUND(((H10/H$9)*100),0)) -> 70
A11: 2 | B11: ANUSHA V | C11: 23 | D11: =IF(UPPER(C11)="AB","AB",ROUND(((C11/C$9)*100),0)) -> 58 | F11: 2 | G11: ANUSHA V | H11: =C11 -> 23 | I11: =IF(UPPER(H11)="AB","AB",ROUND(((H11/H$9)*100),0)) -> 58
A12: 3 | B12: ANUSHREE BEHERA | C12: 27 | D12: =IF(UPPER(C12)="AB","AB",ROUND(((C12/C$9)*100),0)) -> 68 | F12: 3 | G12: ANUSHREE BEHERA | H12: =C12 -> 27 | I12: =IF(UPPER(H12)="AB","AB",ROUND(((H12/H$9)*100),0)) -> 68
A13: 4 | B13: ARNESHA DEBNATH | C13: 32 | D13: =IF(UPPER(C13)="AB","AB",ROUND(((C13/C$9)*100),0)) -> 80 | F13: 4 | G13: ARNESHA DEBNATH | H13: =C13 -> 32 | I13: =IF(UPPER(H13)="AB","AB",ROUND(((H13/H$9)*100),0)) -> 80
A14: 5 | B14: ARSALA KHATUN | C14: 21 | D14: =IF(UPPER(C14)="AB","AB",ROUND(((C14/C$9)*100),0)) -> 53 | F14: 5 | G14: ARSALA KHATUN | H14: =C14 -> 21 | I14: =IF(UPPER(H14)="AB","AB",ROUND(((H14/H$9)*100),0)) -> 53
A15: 6 | B15: BAISHALI DEBNATH | C15: 30 | D15: =IF(UPPER(C15)="AB","AB",ROUND(((C15/C$9)*100),0)) -> 75 | F15: 6 | G15: BAISHALI DEBNATH | H15: =C15 -> 30 | I15: =IF(UPPER(H15)="AB","AB",ROUND(((H15/H$9)*100),0)) -> 75
A16: 7 | B16: BIPASHA DEBNATH | C16: 35 | D16: =IF(UPPER(C16)="AB","AB",ROUND(((C16/C$9)*100),0)) -> 88 | F16: 7 | G16: BIPASHA DEBNATH | H16: =C16 -> 35 | I16: =IF(UPPER(H16)="AB","AB",ROUND(((H16/H$9)*100),0)) -> 88
A17: 8 | B17: CHANDRA DAS | C17: 20 | D17: =IF(UPPER(C17)="AB","AB",ROUND(((C17/C$9)*100),0)) -> 50 | F17: 8 | G17: CHANDRA DAS | H17: =C17 -> 20 | I17: =IF(UPPER(H17)="AB","AB",ROUND(((H17/H$9)*100),0)) -> 50
A18: 9 | B18: JENISHA DEBBARMA | C18: 25 | D18: =IF(UPPER(C18)="AB","AB",ROUND(((C18/C$9)*100),0)) -> 63 | F18: 9 | G18: JENISHA DEBBARMA | H18: =C18 -> 25 | I18: =IF(UPPER(H18)="AB","AB",ROUND(((H18/H$9)*100),0)) -> 63
A19: 10 | B19: JIYA DEBBARMA | C19: 24 | D19: =IF(UPPER(C19)="AB","AB",ROUND(((C19/C$9)*100),0)) -> 60 | F19: 10 | G19: JIYA DEBBARMA | H19: =C19 -> 24 | I19: =IF(UPPER(H19)="AB","AB",ROUND(((H19/H$9)*100),0)) -> 60
A20: 11 | B20: JOYDIPA DAS | C20: 21 | D20: =IF(UPPER(C20)="AB","AB",ROUND(((C20/C$9)*100),0)) -> 53 | F20: 11 | G20: JOYDIPA DAS | H20: =C20 -> 21 | I20: =IF(UPPER(H20)="AB","AB",ROUND(((H20/H$9)*100),0)) -> 53
A21: 12 | B21: MAITRI MAJUMDER | C21: 26 | D21: =IF(UPPER(C21)="AB","AB",ROUND(((C21/C$9)*100),0)) -> 65 | F21: 12 | G21: MAITRI MAJUMDER | H21: =C21 -> 26 | I21: =IF(UPPER(H21)="AB","AB",ROUND(((H21/H$9)*100),0)) -> 65
... A25: 16 | B25: SANVI ROY | C25: 37 | D25: =IF(UPPER(C25)="AB","AB",ROUND(((C25/C$9)*100),0)) -> 93 | F25: 16 | G25: SANVI ROY | H25: =C25 -> 37 | I25: =IF(UPPER(H25)="AB","AB",ROUND(((H25/H$9)*100),0)) -> 93
A26: 17 | B26: SUPARNA DAS | C26: 27 | D26: =IF(UPPER(C25)="AB","AB",ROUND(((C25/C$9)*100),0)) -> 93 | F26: 17 | G26: SUPARNA DAS | H26: =C26 -> 27 | I26: =IF(UPPER(H26)="AB","AB",ROUND(((H26/H$9)*100),0)) -> 68
A27: 18 | B27: TANEESHA PANUA | C27: 35 | D27: =IF(UPPER(C26)="AB","AB",ROUND(((C26/C$9)*100),0)) -> 68 | F27: 18 | G27: TANEESHA PANUA | H27: =C27 -> 35 | I27: =IF(UPPER(H27)="AB","AB",ROUND(((H27/H$9)*100),0)) -> 88
A28: 19 | B28: TANHA AKTER | C28: 32 | D28: =IF(UPPER(C27)="AB","AB",ROUND(((C27/C$9)*100),0)) -> 88 | F28: 19 | G28: TANHA AKTER | H28: =C28 -> 32 | I28: =IF(UPPER(H28)="AB","AB",ROUND(((H28/H$9)*100),0)) -> 80
A29: 20 | B29: ADRISH RAKSHIT | C29: 35 | D29: =IF(UPPER(C28)="AB","AB",ROUND(((C28/C$9)*100),0)) -> 80 | F29: 20 | G29: ADRISH RAKSHIT | H29: =C29 -> 35 | I29: =IF(UPPER(H29)="AB","AB",ROUND(((H29/H$9)*100),0)) -> 88
A30: 21 | B30: ARNAV DEY | C30: 26 | D30: =IF(UPPER(C29)="AB","AB",ROUND(((C29/C$9)*100),0)) -> 88 | F30: 21 | G30: ARNAV DEY | H30: =C30 -> 26 | I30: =IF(UPPER(H30)="AB","AB",ROUND(((H30/H$9)*100),0)) -> 65
A31: 22 | B31: ATIF ALAM | C31: 34 | D31: =IF(UPPER(C30)="AB","AB",ROUND(((C30/C$9)*100),0)) -> 65 | F31: 22 | G31: ATIF ALAM | H31: =C31 -> 34 | I31: =IF(UPPER(H31)="AB","AB",ROUND(((H31/H$9)*100),0)) -> 85
A32: 23 | B32: AYASH DEBBARMA | C32: 30 | D32: =IF(UPPER(C31)="AB","AB",ROUND(((C31/C$9)*100),0)) -> 85 | F32: 23 | G32: AYASH DEBBARMA | H32: =C32 -> 30 | I32: =IF(UPPER(H32)="AB","AB",ROUND(((H32/H$9)*100),0)) -> 75
A33: 24 | B33: DEBAJYOTI RUDRAPAL | C33: 31 | D33: =IF(UPPER(C32)="AB","AB",ROUND(((C32/C$9)*100),0)) -> 75 | F33: 24 | G33: DEBAJYOTI RUDRAPAL | H33: =C33 -> 31 | I33: =IF(UPPER(H33)="AB","AB",ROUND(((H33/H$9)*100),0)) -> 78
A34: 25 | B34: DEEP RAJ BHOWMIK | C34: 36 | D34: =IF(UPPER(C33)="AB","AB",ROUND(((C33/C$9)*100),0)) -> 78 | F34: 25 | G34: DEEP RAJ BHOWMIK | H34: =C34 -> 36 | I34: =IF(UPPER(H34)="AB","AB",ROUND(((H34/H$9)*100),0)) -> 90
A35: 26 | B35: EMAN HUSSEN | C35: 34 | D35: =IF(UPPER(C34)="AB","AB",ROUND(((C34/C$9)*100),0)) -> 90 | F35: 26 | G35: EMAN HUSSEN | H35: =C35 -> 34 | I35: =IF(UPPER(H35)="AB","AB",ROUND(((H35/H$9)*100),0)) -> 85
A36: 27 | B36: KHAKWCHANG DEBBARMA | C36: 24 | D36: =IF(UPPER(C35)="AB","AB",ROUND(((C35/C$9)*100),0)) -> 85 | F36: 27 | G36: KHAKWCHANG DEBBARMA | H36: =C36 -> 24 | I36: =IF(UPPER(H36)="AB","AB",ROUND(((H36/H$9)*100),0)) -> 60
A37: 28 | B37: KUSH GUPTA | C37: 29 | D37: =IF(UPPER(C36)="AB","AB",ROUND(((C36/C$9)*100),0)) -> 60 | F37: 28 | G37: KUSH GUPTA | H37: =C37 -> 29 | I37: =IF(UPPER(H37)="AB","AB",ROUND(((H37/H$9)*100),0)) -> 73
... A46: 37 | B46: SAURAV SINHA | C46: 25 | D46: =IF(UPPER(C45)="AB","AB",ROUND(((C45/C$9)*100),0)) -> 88 | F46: 37 | G46: SAURAV SINHA | H46: =C46 -> 25 | I46: =IF(UPPER(H46)="AB","AB",ROUND(((H46/H$9)*100),0)) -> 63
A47: 38 | B47: SHANTANU DAS | C47: 20 | D47: =IF(UPPER(C47)="AB","AB",ROUND(((C47/C$9)*100),0)) -> 50 | F47: 38 | G47: SHANTANU DAS | H47: =C47 -> 20 | I47: =IF(UPPER(H47)="AB","AB",ROUND(((H47/H$9)*100),0)) -> 50
A48: 39 | B48: SHARTHAKI RUDRA PAUL | C48: 29 | D48: =IF(UPPER(C48)="AB","AB",ROUND(((C48/C$9)*100),0)) -> 73 | F48: 39 | G48: SHARTHAKI RUDRA PAUL | H48: =C48 -> 29 | I48: =IF(UPPER(H48)="AB","AB",ROUND(((H48/H$9)*100),0)) -> 73
A49: 40 | B49: SOMYANSHU SAHOO | C49: 32 | D49: =IF(UPPER(C49)="AB","AB",ROUND(((C49/C$9)*100),0)) -> 80 | F49: 40 | G49: SOMYANSHU SAHOO | H49: =C49 -> 32 | I49: =IF(UPPER(H49)="AB","AB",ROUND(((H49/H$9)*100),0)) -> 80
A50: 41 | B50: SUDIP ROY | C50: 24 | D50: =IF(UPPER(C50)="AB","AB",ROUND(((C50/C$9)*100),0)) -> 60 | F50: 41 | G50: SUDIP ROY | H50: =C50 -> 24 | I50: =IF(UPPER(H50)="AB","AB",ROUND(((H50/H$9)*100),0)) -> 60
A51: 42 | B51: SUMANTA DEBBARMA | C51: 23 | D51: =IF(UPPER(C51)="AB","AB",ROUND(((C51/C$9)*100),0)) -> 58 | F51: 42 | G51: SUMANTA DEBBARMA | H51: =C51 -> 23 | I51: =IF(UPPER(H51)="AB","AB",ROUND(((H51/H$9)*100),0)) -> 58
...

Sheet Result Analysis
A1: KENDRIYA VIDYALAYA NIT AGARTALA
A2: PARENT TEACHER MEETING
A3: Date : 07-11-2025 | F3: SESSION : 2025-26 | M3: VI PT2
A4: Roll No. | B4: Name of Student | C4: Hin | D4: Eng | E4: Math | F4: Scie | G4: S.St. | H4: Skt | I4: A.I. | J4: Total | K4: % Marks | L4: Remarks | M4: Sign. of Parents
B5: M.M.-> | C5: 40 | D5: 40 | E5: 40 | F5: 40 | G5: 40 | H5: 40 | I5: 40 | J5: 240 | K5: 100
A6: 1 | B6: ALIA AKTAR | C6: =हिन्दी!C10 -> 21 | D6: =English!C10 -> 27 | E6: =Maths!C10 -> 15 | F6: =Science!C10 -> 20 | G6: =S.St.!C10 -> 14 | H6: =संस्कृत!C10 -> 23 | I6: =AI!C10 -> 28 | J6: =SUM(C6:H6) -> 120 | K6: =J6/240*100 -> 50 | M6: 0
A7: 2 | B7: ANUSHA V | C7: =हिन्दी!C11 -> 41 | D7: =English!C11 -> 10 | E7: =Maths!C11 -> 10 | F7: =Science!C11 -> 9 | G7: =S.St.!C11 -> 6 | H7: =संस्कृत!C11 -> 20 | I7: =AI!C11 -> 23 | J7: =SUM(C7:H7) -> 96 | K7: =J7/240*100 -> 40 | M7: 1
A8: 3 | B8: ANUSHREE BEHERA | C8: =हिन्दी!C12 -> 52 | D8: =English!C12 -> 17 | E8: =Maths!C12 -> 28 | F8: =Science!C12 -> 24 | G8: =S.St.!C12 -> 25 | H8: =संस्कृत!C12 -> 32 | I8: =AI!C12 -> 27 | J8: =SUM(C8:H8) -> 178 | K8: =J8/240*100 -> 74.166667 | M8: 0
A9: 4 | B9: ARNESHA DEBNATH | C9: =हिन्दी!C13 -> 51 | D9: =English!C13 -> 30 | E9: =Maths!C13 -> 29 | F9: =Science!C13 -> 30 | G9: =S.St.!C13 -> 25 | H9: =संस्कृत!C13 -> 34 | I9: =AI!C13 -> 32 | J9: =SUM(C9:H9) -> 199 | K9: =J9/240*100 -> 82.916667 | M9: 1
A10: 5 | B10: ARSALA KHATUN | C10: =हिन्दी!C14 -> 45 | D10: =English!C14 -> 24 | E10: =Maths!C14 -> 20 | F10: =Science!C14 -> 20 | G10: =S.St.!C14 -> 16 | H10: =संस्कृत!C14 -> 29 | I10: =AI!C14 -> 21 | J10: =SUM(C10:H10) -> 154 | K10: =J10/240*100 -> 64.166667 | M10: 0
A11: 6 | B11: BAISHALI DEBNATH | C11: =हिन्दी!C15 -> 36 | D11: =English!C15 -> 27 | E11: =Maths!C15 -> 30 | F11: =Science!C15 -> 26 | G11: =S.St.!C15 -> 19 | H11: =संस्कृत!C15 -> 34 | I11: =AI!C15 -> 30 | J11: =SUM(C11:H11) -> 172 | K11: =J11/240*100 -> 71.666667 | M11: 0
A12: 7 | B12: BIPASHA DEBNATH | C12: =हिन्दी!C16 -> 49 | D12: =English!C16 -> 35 | E12: =Maths!C16 -> 30 | F12: =Science!C16 -> 35 | G12: =S.St.!C16 -> 31 | H12: =संस्कृत!C16 -> 40 | I12: =AI!C16 -> 35 | J12: =SUM(C12:H12) -> 220 | K12: =J12/240*100 -> 91.666667 | M12: 1
A13: 8 | B13: CHANDRA DAS | C13: =हिन्दी!C17 -> 13 | D13: =English!C17 -> 6 | E13: =Maths!C17 -> 5 | F13: =Science!C17 -> 2 | G13: =S.St.!C17 -> 4 | H13: =संस्कृत!C17 -> 13 | I13: =AI!C17 -> 20 | J13: =SUM(C13:H13) -> 43 | K13: =J13/240*100 -> 17.916667
A14: 9 | B14: JENISHA DEBBARMA | C14: =हिन्दी!C18 -> 30 | D14: =English!C18 -> 24 | E14: =Maths!C18 -> 10 | F14: =Science!C18 -> 9 | G14: =S.St.!C18 -> 10 | H14: =संस्कृत!C18 -> 25 | I14: =AI!C18 -> 25 | J14: =SUM(C14:H14) -> 108 | K14: =J14/240*100 -> 45 | M14: 1
A15: 10 | B15: JIYA DEBBARMA | C15: =हिन्दी!C19 -> 12 | D15: =English!C19 -> 9 | E15: =Maths!C19 -> 3 | F15: =Science!C19 -> 4 | G15: =S.St.!C19 -> 4 | H15: =संस्कृत!C19 -> 19 | I15: =AI!C19 -> 24 | J15: =SUM(C15:H15) -> 51 | K15: =J15/240*100 -> 21.25 | M15: 0
A16: 11 | B16: JOYDIPA DAS | C16: =हिन्दी!C20 -> 6 | D16: =English!C20 -> 11 | E16: =Maths!C20 -> 9 | F16: =Science!C20 -> 6 | G16: =S.St.!C20 -> 7 | H16: =संस्कृत!C20 -> 27 | I16: =AI!C20 -> 21 | J16: =SUM(C16:H16) -> 66 | K16: =J16/240*100 -> 27.5 | M16: 1
A17: 12 | B17: MAITRI MAJUMDER | C17: =हिन्दी!C21 -> 34 | D17: =English!C21 -> 11 | E17: =Maths!C21 -> 14 | F17: =Science!C21 -> 8 | G17: =S.St.!C21 -> 11 | H17: =संस्कृत!C21 -> 17 | I17: =AI!C21 -> 26 | J17: =SUM(C17:H17) -> 95 | K17: =J17/240*100 -> 39.583333 | M17: 0
A18: 13 | B18: NISHA BHOWMIK | C18: =हिन्दी!C22 -> 34 | D18: =English!C22 -> 24 | E18: =Maths!C22 -> 19 | F18: =Science!C22 -> 18 | G18: =S.St.!C22 -> 20 | H18: =संस्कृत!C22 -> 27 | I18: =AI!C22 -> 18 | J18: =SUM(C18:H18) -> 142 | K18: =J18/240*100 -> 59.166667 | M18: 1
A19: 14 | B19: PALLABI DATTA | C19: =हिन्दी!C23 -> 46 | D19: =English!C23 -> 29 | E19: =Maths!C23 -> 25 | F19: =Science!C23 -> 17 | G19: =S.St.!C23 -> 21 | H19: =संस्कृत!C23 -> 37 | I19: =AI!C23 -> 28 | J19: =SUM(C19:H19) -> 175 | K19: =J19/240*100 -> 72.916667 | M19: 0
A20: 15 | B20: PAYEL SANGMA | C20: =हिन्दी!C24 -> 36 | D20: =English!C24 -> 23 | E20: =Maths!C24 -> 14 | F20: =Science!C24 -> 16 | G20: =S.St.!C24 -> 21 | H20: =संस्कृत!C24 -> 30 | I20: =AI!C24 -> 29 | J20: =SUM(C20:H20) -> 140 | K20: =J20/240*100 -> 58.333333 | M20: 1
A21: 16 | B21: SANVI ROY | C21: =हिन्दी!C25 -> 52 | D21: =English!C25 -> 32 | E21: =Maths!C25 -> 27 | F21: =Science!C25 -> 19 | G21: =S.St.!C25 -> 25 | H21: =संस्कृत!C25 -> 33 | I21: =AI!C25 -> 37 | J21: =SUM(C21:H21) -> 188 | K21: =J21/240*100 -> 78.333333 | M21: 1
A22: 17 | B22: SUPARNA DAS | C22: =हिन्दी!C26 -> 10 | D22: =English!C26 -> 12 | E22: =Maths!C26 -> 10 | F22: =Science!C26 -> 4 | G22: =S.St.!C26 -> 8 | H22: =संस्कृत!C26 -> 38 | I22: =AI!C25 -> 37 | J22: =SUM(C22:H22) -> 82 | K22: =J22/240*100 -> 34.166667 | M22: 0
A23: 18 | B23: TANEESHA PANUA | C23: =हिन्दी!C27 -> 56 | D23: =English!C27 -> 39 | E23: =Maths!C27 -> 40 | F23: =Science!C27 -> 37 | G23: =S.St.!C27 -> 39 | H23: =संस्कृत!C27 -> 40 | I23: =AI!C26 -> 27 | J23: =SUM(C23:H23) -> 251 | K23: =J23/240*100 -> 104.58333 | M23: 1
A24: 19 | B24: TANHA AKTER | C24: =हिन्दी!C28 -> 16 | D24: =English!C28 -> 26 | E24: =Maths!C28 -> 16 | F24: =Science!C28 -> 11 | G24: =S.St.!C28 -> 16 | H24: =संस्कृत!C28 -> 27 | I24: =AI!C27 -> 35 | J24: =SUM(C24:H24) -> 112 | K24: =J24/240*100 -> 46.666667 | M24: 0
A25: 20 | B25: ADRISH RAKSHIT | C25: =हिन्दी!C29 -> 58 | D25: =English!C29 -> 37 | E25: =Maths!C29 -> 39 | F25: =Science!C29 -> 33 | G25: =S.St.!C29 -> 39 | H25: =संस्कृत!C29 -> 35 | I25: =AI!C28 -> 32 | J25: =SUM(C25:H25) -> 241 | K25: =J25/240*100 -> 100.41667 | M25: 0
A26: 21 | B26: ARNAV DEY | C26: =हिन्दी!C30 -> 23 | D26: =English!C30 -> 8 | E26: =Maths!C30 -> 13 | F26: =Science!C30 -> 5 | G26: =S.St.!C30 -> 6 | H26: =संस्कृत!C30 -> 27 | I26: =AI!C29 -> 35 | J26: =SUM(C26:H26) -> 82 | K26: =J26/240*100 -> 34.166667 | M26: 0
A27: 22 | B27: ATIF ALAM | C27: =हिन्दी!C31 -> 27 | D27: =English!C31 -> 23 | E27: =Maths!C31 -> 24 | F27: =Science!C31 -> 26 | G27: =S.St.!C31 -> 22 | H27: =संस्कृत!C31 -> 17 | I27: =AI!C30 -> 26 | J27: =SUM(C27:H27) -> 139 | K27: =J27/240*100 -> 57.916667 | M27: 0
A28: 23 | B28: AYASH DEBBARMA | C28: =हिन्दी!C32 -> 48 | D28: =English!C32 -> 22 | E28: =Maths!C32 -> 14 | F28: =Science!C32 -> 26 | G28: =S.St.!C32 -> 29 | H28: =संस्कृत!C32 -> 33 | I28: =AI!C31 -> 34 | J28: =SUM(C28:H28) -> 172 | K28: =J28/240*100 -> 71.666667 | M28: 0
A29: 24 | B29: DEBAJYOTI RUDRAPAL | C29: =हिन्दी!C33 -> 55 | D29: =English!C33 -> 37 | E29: =Maths!C33 -> 37 | F29: =Science!C33 -> 36 | G29: =S.St.!C33 -> 37 | H29: =संस्कृत!C33 -> 39 | I29: =AI!C32 -> 30 | J29: =SUM(C29:H29) -> 241 | K29: =J29/240*100 -> 100.41667 | M29: 0
A30: 25 | B30: DEEP RAJ BHOWMIK | C30: =हिन्दी!C34 -> 6 | D30: =English!C34 -> 13 | E30: =Maths!C34 -> 9 | F30: =Science!C34 -> 13 | G30: =S.St.!C34 -> 10 | H30: =संस्कृत!C34 -> 20 | I30: =AI!C33 -> 31 | J30: =SUM(C30:H30) -> 71 | K30: =J30/240*100 -> 29.583333 | M30: 0
A31: 26 | B31: EMAN HUSSEN | C31: =हिन्दी!C35 -> 15 | D31: =English!C35 -> 6 | E31: =Maths!C35 -> 11 | F31: =Science!C35 -> 16 | G31: =S.St.!C35 -> 14 | H31: =संस्कृत!C35 -> 24 | I31: =AI!C34 -> 36 | J31: =SUM(C31:H31) -> 86 | K31: =J31/240*100 -> 35.833333 | M31: 0
A32: 27 | B32: KHAKWCHANG DEBBARMA | C32: =हिन्दी!C36 -> 11 | D32: =English!C36 -> 4 | E32: =Maths!C36 -> 5 | F32: =Science!C36 -> 4 | G32: =S.St.!C36 -> 3 | H32: =संस्कृत!C36 -> 9 | I32: =AI!C35 -> 34 | J32: =SUM(C32:H32) -> 36 | K32: =J32/240*100 -> 15 | M32: 1
A33: 28 | B33: KUSH GUPTA | C33: =हिन्दी!C37 -> 38 | D33: =English!C37 -> 14 | E33: =Maths!C37 -> 31 | F33: =Science!C37 -> 25 | G33: =S.St.!C37 -> 28 | H33: =संस्कृत!C37 -> 21 | I33: =AI!C36 -> 24 | J33: =SUM(C33:H33) -> 157 | K33: =J33/240*100 -> 65.416667 | M33: 0
... A39: 34 | B39: RIK DEBNATH | C39: =हिन्दी!C43 -> 42 | D39: =English!C43 -> 25 | E39: =Maths!C43 -> 19 | F39: =Science!C43 -> 19 | G39: =S.St.!C43 -> 19 | H39: =संस्कृत!C43 -> 15 | I39: =AI!C42 -> 14 | J39: =SUM(C39:H39) -> 139 | K39: =J39/240*100 -> 57.916667 | M39: 0
A40: 35 | B40: ROHITH KRISHNA R | C40: =हिन्दी!C44 -> 33 | D40: =English!C44 -> 16 | E40: =Maths!C44 -> 14 | F40: =Science!C44 -> 15 | G40: =S.St.!C44 -> 15 | H40: =संस्कृत!C44 -> 16 | I40: =AI!C43 -> 37 | J40: =SUM(C40:H40) -> 109 | K40: =J40/240*100 -> 45.416667
A41: 36 | B41: ROHIT KUMAR | C41: =हिन्दी!C45 -> 48 | D41: =English!C45 -> 23 | E41: =Maths!C45 -> 22 | F41: =Science!C45 -> 26 | G41: =S.St.!C45 -> 26 | H41: =संस्कृत!C45 -> 18 | I41: =AI!C44 -> 29 | J41: =SUM(C41:H41) -> 163 | K41: =J41/240*100 -> 67.916667
A42: 37 | B42: SAURAV SINHA | C42: =हिन्दी!C46 -> 37 | D42: =English!C46 -> 26 | E42: =Maths!C46 -> 12 | F42: =Science!C46 -> 13 | G42: =S.St.!C46 -> 9 | H42: =संस्कृत!C46 -> 30 | I42: =AI!C45 -> 35 | J42: =SUM(C42:H42) -> 127 | K42: =J42/240*100 -> 52.916667
A43: 38 | B43: SHANTANU DAS | C43: =हिन्दी!C47 -> 21 | D43: =English!C47 -> 11 | E43: =Maths!C47 -> AB | F43: =Science!C47 -> 8 | G43: =S.St.!C47 -> 7 | H43: =संस्कृत!C47 -> 21 | I43: =AI!C47 -> 20 | J43: =SUM(C43:H43) -> 68 | K43: =J43/240*100 -> 28.333333
A44: 39 | B44: SHARTHAKI RUDRA PAUL | C44: =हिन्दी!C48 -> 36 | D44: =English!C48 -> 24 | E44: =Maths!C48 -> 36 | F44: =Science!C48 -> 21 | G44: =S.St.!C48 -> 30 | H44: =संस्कृत!C48 -> 25 | I44: =AI!C48 -> 29 | J44: =SUM(C44:H44) -> 172 | K44: =J44/240*100 -> 71.666667
A45: 40 | B45: SOMYANSHU SAHOO | C45: =हिन्दी!C49 -> 30 | D45: =English!C49 -> 17 | E45: =Maths!C49 -> 24 | F45: =Science!C49 -> 10 | G45: =S.St.!C49 -> 18 | H45: =संस्कृत!C49 -> 25 | I45: =AI!C49 -> 32 | J45: =SUM(C45:H45) -> 124 | K45: =J45/240*100 -> 51.666667
...
