Workbook

Sheet AllStudentDetails
A1: R.NO. | B1: Adm Year | C1: Admn No | D1: DOA | E1: Student Name | F1: house | G1: Date Of Birth | H1: Gender | I1: Category | J1: Admn Category | K1: Mothers Name | L1: Mobile No | M1: M OCCUPATION | N1: Fathers Name | O1: F OCCUPATION | P1: ADDRESS | Q1: ADMISSION CLASS | R1: QUOTA | S1: BG | T1: Single Girl Child | U1: RTE | V1: Minority | W1: Email ID | X1: UBI ID | Y1: Aadhar Card No | Z1: APPAR ID | AA1: PEN | AB1: Reimbursement Claimed | AC1: Total Quarterly Fee | AE1: REMARK
A2: 1 | B2: 2020 | C2: 823 | D2: 44079 | E2: ALIA AKTAR | F2: Ashoka | G2: 18/08/2014 | H2: Girl | I2: General | J2: VI | K2: NAJNU BEGAM | L2: 8415912652 | M2: HOUSEWIFE | N2: AKBAR HOSSEN | O2: TRIPURA POLICE CONTRACTUAL | P2: RANIR BAZAR | Q2: I | R2: SGC | S2: B+ | T2: YES | V2: Muslim | W2: begamnajnu823@gmail.com | X2: 182206120000823 | Y2: 909487193316 | Z2: 165294266279 | AA2: 21913998630 | AC2: 0
A3: 2 | B3: 2020 | C3: 791 | D3: 44057 | E3: ANUSHA V | F3: Raman | G3: 01/08/2014 | H3: Girl | I3: OBC(NCL) | J3: IV | K3: V. MANIKA | L3: 9774747303 | M3: HOUSEWIFE | N3: K. VELMURUGAN | O3: TSR | P3: PASCHIM BARJALA JIRANIA | Q3: I | R3: RTE | S3: AB+ | U3: YES | W3: vmurugan19@gmail.com | X3: 182206120000791 | Y3: 948124324792 | Z3: 456889587223 | AA3: 22248657527 | AC3: 0
A4: 3 | B4: 2020 | C4: 820 | D4: 44071 | E4: ANUSHREE BEHERA | F4: Tagore | G4: 19/06/2013 | H4: Girl | I4: OBC(NCL) | J4: IV | K4: MINATI BEHERA | L4: 9863212397 | M4: HOUSEWIFE | N4: ARUNA KUMAR BEHERA | O4: TSR | P4: 10 BN TSR | Q4: I | S4: B+ | W4: minatib747@gmail.com | X4: 182206120000820 | Y4: 305275447142 | Z4: 662701038915 | AA4: 21911964729 | AC4: 1800 | AE4: NAME NEEDS TO BE UPDATED ON UDISE
A5: 4 | B5: 2020 | C5: 813 | D5: 44069 | E5: ARNESHA DEBNATH | F5: Subhash | G5: 02/08/2013 | H5: Girl | I5: OBC(NCL) | J5: VI | K5: PRATIVA DEBNATH | L5: 9089138932 | M5: HOUSEWIFE | N5: UTTAM DEBNATH | O5: PVT JOB | P5: RANIR BAZAR | Q5: I | S5: O- | T5: YES | W5: uttam.rsu@gmail.com | X5: 182206120000813 | Y5: 312353395012 | Z5: 583169840093 | AA5: 22253346358 | AC5: 1800
A6: 5 | B6: 2020 | C6: 828 | D6: 44085 | E6: ARSALA KHATUN | F6: Ashoka | G6: 01/04/2015 | H6: Girl | I6: General | J6: IV | K6: TAMANNA KHATUN | L6: 8738867693 | M6: HOUSEWIFE | N6: MD ZAWED KHAN | O6: 10 TSR | P6: 10 TSR | Q6: I | S6: B- | V6: Muslim | W6: zawed9402120902@gmail.com | X6: 182206120000828 | Y6: 722342112084 | Z6: 806896102557 | AA6: 22278174743 | AC6: 1800
A7: 6 | B7: 2020 | C7: 795 | D7: 44061 | E7: BAISHALI DEBNATH | F7: Raman | G7: 23/01/2014 | H7: Girl | I7: OBC(CL) | J7: II | K7: SUBHADRA DEBNATH | L7: 6909441754 | M7: HOUSEWIFE | N7: BIJOY DEBNATH | O7: CRPF | P7: BAGMARA BIKRAM SEKERKOTE | Q7: I | R7: SAQ | S7: O+ | W7: sdsubhadra123@gmail.com | X7: 182206120000795 | Y7: 741215440017 | Z7: 857308359022 | AA7: 22061469809 | AB7: YES | AC7: 1800
A8: 7 | B8: 2020 | C8: 799 | D8: 44064 | E8: BIPASHA DEBNATH | F8: Tagore | G8: 30/12/2014 | H8: Girl | I8: OBC(NCL) | J8: IV | K8: SONAI BISWAS DEBNATH | L8: 9862290068 | M8: STATE GOVT STORE KEEPER(BDO) | N8: BIPLAB DEBNATH | O8: SELF EMPLOYED | P8: OLD AGARTALA | Q8: I | S8: A+ | T8: YES | W8: debnath1977@gmail.com | X8: 182206120000799 | Y8: 567600460596 | Z8: 379252524935 | AA8: 22372954329 | AC8: 0
A9: 8 | B9: 2020 | C9: 790 | D9: 44057 | E9: CHANDRA DAS | F9: Subhash | G9: 02/11/2014 | H9: Girl | I9: SC | J9: VI | K9: RUPALI DAS | L9: 9862200422 | M9: HOUSEWIFE | N9: MADHU SUDHAN DAS | O9: BUSINESS | P9: NOABADI JIRANIA | Q9: I | R9: RTE | S9: A+ | U9: YES | W9: rupalidas32586@gmail.com | X9: 182206120000790 | Y9: 442179783699 | Z9: 926172639220 | AA9: 22343135862 | AC9: 0
A10: 9 | B10: 2020 | C10: 802 | D10: 44057 | E10: JENISHA DEBBARMA | F10: Ashoka | G10: 14/10/2014 | H10: Girl | I10: ST | J10: VI | K10: SUBHA LAXMI DEBBARMA | L10: 9089468304 | M10: HOUSEWIFE | N10: RAJENDRA DEBBARMA | O10: BUSINESS | P10: RANIR BAZAR | Q10: I | R10: RTE | S10: O+ | U10: YES | W10: debbarmarajendra143000@gmail.com | X10: 182206120000802 | Y10: 422179205695 | Z10: 970357897795 | AA10: 21871834384 | AC10: 0
A11: 10 | B11: 2020 | C11: 797 | D11: 44061 | E11: JIYA DEBBARMA | F11: Raman | G11: 27/03/2015 | H11: Girl | I11: ST | J11: II | K11: MOUSUMI DEBBARMA | L11: 8787343533 | M11: HOUSEWIFE | N11: BISWAMANI DEBBARMA | O11: INDIAN ARMY | P11: BHADRA MISHAP PARA | Q11: I | S11: O+ | W11: bdbarmanbarman444@gmail.com | X11: 182206120000797 | Y11: 500247146871 | Z11: 229047785761 | AA11: 21905031727 | AC11: 1800
A12: 11 | B12: 2020 | C12: 803 | D12: 44057 | E12: JOYDIPA DAS | F12: Raman | G12: 08/07/2014 | H12: Girl | I12: SC | J12: VI | K12: JALI PAUL DAS | L12: 7005059205 | M12: HOUSEWIFE | N12: PINTU DAS | O12: BUSINESS | P12: KOBRA PARA JIRANIA | Q12: I | R12: RTE | S12: A+ | U12: YES | W12: jalipaul1957@gmail.com | X12: 182206120000803 | Y12: 264862921965 | Z12: 485723613525 | AA12: 21885219265 | AC12: 0
A13: 12 | B13: 2020 | C13: 822 | D13: 44076 | E13: MAITRI MAJUMDER | F13: Tagore | G13: 16/08/2014 | H13: Girl | I13: OBC(NCL) | J13: VI | K13: MANDIRA KURI MAJUMDER | L13: 8787558005 | M13: HOUSEWIFE | N13: MITHAN MAJUMDER | O13: SELF EMPLOYED | P13: RANIR KHAMAR | Q13: I | S13: A+ | W13: majundermithan147@gmail.com | X13: 182206120000822 | Y13: 887962002526 | Z13: 898268188636 | AA13: 22432155347 | AC13: 1800
A14: 13 | B14: 2020 | C14: 821 | D14: 44074 | E14: NISHA BHOWMIK | F14: Tagore | G14: 29/07/2014 | H14: Girl | I14: SC | J14: IV | K14: SWAPNA DAS (BHOWMIK) | L14: 9863609030 | M14: HOUSEWIFE | N14: NIHAR BHOWMIK | O14: STATE GOVT | P14: KOBRA KHAMAR | Q14: I | R14: RTE | S14: B+ | U14: YES | W14: riyaabhowmik2005@gmail.com | X14: 182206120000821 | Y14: 924349927192 | Z14: 799965593447 | AA14: 22089176287 | AC14: 0
A15: 14 | B15: 2020 | C15: 817 | D15: 44070 | E15: PALLABI DATTA | F15: Subhash | G15: 07/09/2014 | H15: Girl | I15: General | J15: IV | K15: RATIKA DEBBARMA DATTA | L15: 8794587878 | M15: TEACHER STATE GOVT | N15: PRABIR CHANDRA DATTA | O15: PVT JOB | P15: JIRANIA | Q15: I | S15: O+ | W15: prppdatta197-@gmail.com | X15: 182206120000817 | Y15: 578773439740 | Z15: 819429122257 | AA15: 22081363343 | AC15: 1800
A16: 15 | B16: 2020 | C16: 831 | D16: 44089 | E16: PAYEL SANGMA | F16: Ashoka | G16: 27/02/2014 | H16: Girl | I16: ST | J16: IV | K16: SWAPNA DAS (SANGMA) | L16: 9366495717 | M16: HOUSEWIFE | N16: PRANAB SANGMA | O16: 7 BN TSR | P16: BHADRAMI SHIPARA JIRANIA | Q16: I | S16: NA | X16: 182206120000831 | Y16: 639528283032 | Z16: 545810033661 | AA16: 22005384804 | AC16: 1800 | AE16: DOB NEEDS TO BE UPDATED ON UDICE
A17: 16 | B17: 2020 | C17: 796 | D17: 44061 | E17: SANVI ROY | F17: Raman | G17: 14/12/2014 | H17: Girl | I17: OBC(NCL) | J17: VI | K17: MOU TAPADAR (ROY) | L17: 9862764153 | M17: HOUSEWIFE | N17: BIPLAB ROY | O17: SSA (CONTRACTUAL) | P17: JIRANIA | Q17: I | R17: RTE | S17: A+ | U17: YES | W17: mou.tapadar@gmail.com | X17: 182206120000796 | Y17: 541201377845 | Z17: 909524822079 | AA17: 22226362957 | AC17: 0
A18: 17 | B18: 2022 | C18: 961 | D18: 44742 | E18: SUPARNA DAS | F18: Raman | G18: 02/12/2013 | H18: Girl | I18: SC | J18: IV | K18: SOMA DAS | L18: 9366218911 | M18: HOUSEWIFE | N18: KRISHNA DHAN DAS | O18: TSR | P18: MAJLISHPUR RANIR BAZAR | Q18: III | S18: A+ | W18: kdas29556@gmail.com | X18: 182206122000961 | Y18: 708786182671 | Z18: 749078561938 | AA18: 22323931841 | AC18: 1800
A19: 18 | B19: 2020 | C19: 788 | D19: 44060 | E19: TANEESHA PANUA | F19: Subhash | G19: 41901 | H19: Girl | I19: General | J19: I | K19: TAMASI MOYRA (PANUA) | L19: 9862824663 | M19: TEACHER | N19: RAJSEKHAR PANUA | O19: TEACHER NIT | P19: NIT CAMPUS | Q19: I | R19: SAQ | S19: B+ | W19: rspanua@gmail.com | X19: 182206120000788 | Y19: 368228934275 | Z19: 316467017105 | AA19: 21968697656 | AB19: YES | AC19: 1800
A20: 19 | B20: 2020 | C20: 798 | D20: 44060 | E20: TANHA AKTER | F20: Ashoka | G20: 09/08/2014 | H20: Girl | I20: General | J20: VI | K20: RINA BEGAM | L20: 8413879847 | M20: HOUSEWIFE | N20: ABDUL JABBAR MIAH | O20: VSSS(NITA CONTRACTUAL) | P20: BHADRA MISHAP PARA | Q20: I | R20: SGC | S20: O+ | T20: YES | V20: Muslim | W20: jabbarmia2015@gmail.com | X20: 182206120000798 | Y20: 864672797526 | Z20: 207563634804 | AA20: 21988869189 | AC20: 0
A21: 20 | B21: 2020 | C21: 787 | D21: 44057 | E21: ADRISH RAKSHIT | F21: Tagore | G21: 04/06/2013 | H21: Boy | I21: General | J21: I | K21: SUMITA RAKSHIT | L21: 9436767282 | M21: HOUSEWIFE | N21: JAYANTA KUMAR RAKSHIT | O21: ASSISTANT PROFF IN NITA | P21: H4B/04/04 | Q21: I | R21: SAQ | S21: O+ | W21: jayantaraxit@gmail.com | X21: 182206120000787 | Y21: 258002847276 | Z21: 848658000656 | AA21: 21944672060 | AB21: YES | AC21: 1800 | AE21: ADRISH
A22: 21 | B22: 2021 | C22: 907A | D22: 44418 | E22: ARNAV DEY | F22: Raman | G22: 07/12/2013 | H22: Boy | I22: General | J22: VI | K22: MALLIKA DEBNATH (DEY) | L22: 9774542196 | M22: HOUSEWIFE | N22: NAYAN DEY | O22: BUSINESS | P22: RANIRBAZAR | Q22: II | R22: VMC DISCRITISNARY QUOTA | S22: AB+ | W22: dnayan1986@gmail.com | X22: 182206121000907A | Y22: 381188761959 | Z22: 874543567905 | AA22: 21823419175 | AC22: 1800
A23: 22 | B23: 2022 | C23: 962 | D23: 44743 | E23: ATIF ALAM | F23: Raman | G23: 30/05/2013 | H23: Boy | I23: General | J23: IV | K23: ISHRAT PERVEEN | L23: 9862332977 | M23: HOUSEWIFE | N23: IMTIYAZ ALAM | O23: TSR | P23: 10 BN TSR | Q23: III | S23: O+ | V23: Muslim | W23: alamimtiyaz9862@gmail.com | X23: 182206122000962 | Y23: 491501383923 | Z23: 483134687745 | AA23: 22333395643 | AC23: 1800
A24: 23 | B24: 2020 | C24: 801 | D24: 44057 | E24: AYASH DEBBARMA | F24: Subhash | G24: 01/11/2014 | H24: Boy | I24: ST | J24: VI | K24: RINA DEBBARMA | L24: 9862774605 | M24: HOUSEWIFE | N24: SAMENDRA DEBBARMA | O24: BUSINESS | P24: RANIR BAZAR | Q24: I | R24: RTE | S24: B+ | U24: YES | W24: debbarmasamendra212@gmail.com | X24: 182206120000801 | Y24: 351149263133 | Z24: 890588548858 | AA24: 22404590353 | AC24: 0
A25: 24 | B25: 2020 | C25: 789 | D25: 44057 | E25: DEBAJYOTI RUDRAPAL | F25: Ashoka | G25: 25/02/2014 | H25: Boy | I25: OBC(CL) | J25: I | K25: SMITA DAS | L25: 9856027328 | M25: HOUSEWIFE | N25: DWIJEN RUDRAPAL | O25: ASSISTANT PROFF IN NITA | P25: NIT CAMPUS | Q25: I | R25: SAQ | S25: AB+ | W25: dwijen.rudrapal@gmail.com | X25: 182206120000789 | Y25: 485568823938 | Z25: 233440341669 | AA25: 22205197635 | AB25: YES | AC25: 1800
A26: 25 | B26: 2020 | C26: 818 | D26: 44074 | E26: DEEP RAJ BHOWMIK | F26: Tagore | G26: 22/06/2014 | H26: Boy | I26: OBC(CL) | J26: IV | K26: REKHA MALAKAR | L26: 9089570570 | M26: LDC PWD | N26: PRADIP BHOWMIK | O26: BUSINESS | P26: KHAYERPUR | Q26: I | S26: B+ | W26: pradipbhowmik1914@gmail.com | X26: 182206120000818 | Y26: 766844055557 | Z26: 907825228905 | AA26: 22137635577 | AC26: 1800
A27: 26 | B27: 2020 | C27: 819 | D27: 44074 | E27: EMAN HUSSEN | F27: Ashoka | G27: 20/10/2014 | H27: Boy | I27: General | J27: IV | K27: FULAN KHATUN | L27: 7629914573 | M27: HOUSEWIFE | N27: AMIR HUSSEN | O27: STATE GOVT | P27: JIRANIA | Q27: I | S27: A+ | V27: Muslim | W27: amirhussein283@gmail.com | X27: 182206120000819 | Y27: 311111336493 | Z27: 841229011324 | AA27: 22277239712 | AC27: 1800
A28: 27 | B28: 2020 | C28: 827 | D28: 44084 | E28: KHAKWCHANG DEBBARMA | F28: Tagore | G28: 20/02/2014 | H28: Boy | I28: ST | J28: IV | K28: SANDHYA DEBBARMA | L28: 9612705453 | M28: HOUSEWIFE | N28: AJIT DEBBARMA | O28: TRIPURA POLICE | P28: TELIAMURA | Q28: I | S28: O+ | W28: bubutidebbarma@gmail.com | X28: 182206120000827 | Y28: 532183760159 | Z28: 909631579863 | AA28: 21807088937 | AC28: 1800
A29: 28 | B29: 2020 | C29: 812 | D29: 44069 | E29: KUSH GUPTA | F29: Subhash | G29: 08/11/2014 | H29: Boy | I29: OBC(NCL) | J29: IV | K29: ANU KUMARI | L29: 8837216620 | M29: HOUSEWIFE | N29: BIPIN KUMAR | O29: 7 BN TSR | P29: 7 TSR JAMPUI JALA | Q29: I | S29: A+ | W29: bipin2433@gmail.com | X29: 182206120000812 | Y29: 487172948367 | Z29: 508017304281 | AA29: 22208263308 | AC29: 1800
A30: 29 | B30: 2020 | C30: 794 | D30: 44062 | E30: MINTU KUMAR YADAV | F30: Ashoka | G30: 10/02/2015 | H30: Boy | I30: OBC(NCL) | J30: II | K30: URMILA DEVI | L30: 8787861037 | M30: HOUSEWIFE | N30: JOGENDRA NATH YADAV | O30: RAILWAY EMPLOYEE | P30: RAILWAY QUARTERS JIRANIA | Q30: I | R30: SAQ? | S30: AB+ | W30: jogendranathyadav913@gmail.com | X30: 182206120000794 | Y30: 345515389395 | Z30: 855669703043 | AA30: 22314714268 | AB30: YES | AC30: 1800
A31: 30 | B31: 2020 | C31: 805 | D31: 44067 | E31: NAVDEEP SINGH | F31: Raman | G31: 20/03/2015 | H31: Boy | I31: SC | J31: IV | K31: GURNAM KAUR | L31: 8974544401 | M31: HOUSEWIFE | N31: RAMAN KUMAR | O31: GOVT SERVICE TSR | P31: 7 TSR JAMPUI JALA | Q31: I | S31: A+ | V31: Sikh | W31: gurnam08121192@gmail.com | X31: 182206120000805 | Y31: 942925742867 | Z31: 760250614528 | AA31: 21840589394 | AC31: 1800
A32: 31 | B32: 2024 | C32: 1129 | D32: 45534 | E32: NISHTALA VENKATA KAMESWARA VARA PRASAD | F32: Subhash | G32: 20/02/2015 | H32: Boy | I32: General | J32: I | K32: NISHTALA A V S L S B DEVI | L32: 8639481710 | M32: HOUSEWIFE | N32: NISHTALA VENKATA BHARAT | O32: NIT AGARTALA | P32: QTR NO G2/1 GANGA RESI. NITA | Q32: V | S32: A+ | W32: nishtaladevi94@gmail.com | X32: 182206124001129 | Y32: 566690213981 | Z32: 210129636079 | AA32: 20796084105 | AB32: YES | AC32: 1800
A33: 32 | B33: 2020 | C33: 804 | D33: 44065 | E33: OMKAR DEBNATH | F33: Tagore | G33: 16/12/2013 | H33: Boy | I33: OBC(NCL) | J33: IV | K33: NABANITA BHOWMIK DEBNATH | L33: 9436484364 | M33: HOUSEWIFE | N33: MANILAL DEBNATH | O33: TEACHER STATE GOVT | P33: BIRENDRA NAGAR JIRANIA | Q33: I | S33: O+ | W33: manianjan13@gmail.com | X33: 182206120000804 | Y33: 866855162278 | Z33: 617970802900 | AA33: 22416230622 | AC33: 1800
A34: 33 | B34: 2020 | C34: 832 | D34: 44089 | E34: PRITHI RAJ BHOWMIK | F34: Ashoka | G34: 22/06/2014 | H34: Boy | I34: OBC(NCL) | J34: IV | K34: REKHA MALAKAR | L34: 9089570570 | M34: LDC PWD | N34: PRADIP BHOWMIK | O34: BUSINESS | P34: KHAYERPUR | Q34: I | S34: B+ | W34: pradipbhowmik1914@gmail.com | X34: 182206120000832 | Y34: 655252211282 | Z34: 308400315853 | AA34: 22556150842 | AC34: 1800
A35: 34 | B35: 2021 | C35: 845 | D35: 44328 | E35: RIK DEBNATH | F35: Tagore | G35: 15/11/2013 | H35: Boy | I35: OBC(CL) | J35: IV | K35: RAKHI DEBNATH | L35: 9436484558 | M35: HOUSEWIFE | N35: RAJIB DEBNATH | O35: STATE GOVT | P35: BIRENDRA NAGAR JIRANIA | Q35: II | R35: SAQ | S35: O+ | W35: debnathrajib1787@gmail.com | X35: 182206121000845 | Y35: 416151647946 | Z35: 439638087954 | AA35: 21991090230 | AC35: 1800
A36: 35 | B36: 2023 | C36: 1028 | D36: 45094 | E36: ROHITH KRISHNA R | F36: Raman | G36: 19/07/2014 | H36: Boy | I36: SC | J36: IV | K36: DHANYA V | L36: 9612927486 | M36: HOUSEWIFE | N36: RENJITH R | O36: TSR | P36: JAMPUIJALA COLONY, SEPDHIYALA | Q36: IV | R36: KVTC | S36: NA | W36: renjithrtsr@gmail.com | X36: 182206123001028 | Y36: 621667079552 | Z36: 263258106697 | AA36: 22959295227 | AC36: 1800
A37: 36 | B37: 2025 | C37: 1174 | D37: 45777 | E37: ROHIT KUMAR | F37: Subhash | G37: 41500 | H37: Boy | I37: OBC(NCL) | J37: II | K37: SIKHA DEVI | L37: 8974833883 | M37: HOUSEWIFE | N37: RAKESH KUMAR RAJBHAR | O37: RAILWAY EMPLOYEE | P37: QTR NO 7A JIRANIA RLY STATION | Q37: VI | S37: B+ | X37: 182206125001174 | Y37: 916533344222 | Z37: 248913171194 | AA37: 21868309306 | AB37: YES | AC37: 1800
A38: 37 | B38: 2020 | C38: 816 | D38: 44070 | E38: SAURAV SINHA | F38: Tagore | G38: 06/02/2014 | H38: Boy | I38: OBC(CL) | J38: IV | K38: SHIBANI SINHA | L38: 9862492405 | M38: HOUSEWIFE | N38: SUBRATA SINHA | O38: TSR | P38: TSR JIRANIA | Q38: I | S38: O+ | W38: sinhashibani12@gmail.com | X38: 182206120000816 | Y38: 967091386273 | Z38: 749542329152 | AA38: 22236837609 | AC38: 1800
A39: 38 | B39: 2020 | C39: 793 | D39: 44063 | E39: SHANTANU DAS | F39: Subhash | G39: 21/05/2014 | H39: Boy | I39: SC | J39: VI | K39: MANIDIPA DAS | L39: 9862437107 | M39: HOUSEWIFE | N39: PINTU DAS | O39: BUSINESS | P39: SN COLONY JIRANIA | Q39: I | S39: A+ | W39: pd3798@gmail.com | X39: 182206120000793 | Y39: 898549472918 | Z39: 901514074222 | AA39: 22145757227 | AC39: 1800
A40: 39 | B40: 2020 | C40: 800 | D40: 44062 | E40: SHARTHAKI RUDRA PAUL | F40: Ashoka | G40: 13/03/2014 | H40: Boy | I40: OBC(CL) | J40: VI | K40: SWAPNA RUDRA PAUL | L40: 9862671142 | M40: BUSINESS | N40: DILIP RUDRA PAUL | O40: BUSINESS | P40: BIRENDRA NAGAR JIRANIA | Q40: I | R40: RTE | S40: AB+ | U40: YES | W40: rudrapaulswapna01@gmail.com | X40: 182206120000800 | Y40: 385615357977 | Z40: 552941388989 | AA40: 21889218125 | AC40: 0
...

Sheet Tables
A1: Social Category wise Enrollment
A2: Category | B2: Boy | C2: Girl | D2: Grand Total
A3: General | B3: =COUNTIFS(AllStudentDetails!$I:$I, TRIM($A3), AllStudentDetails!$H:$H, B$2) -> 6 | C3: =COUNTIFS(AllStudentDetails!$I:$I, TRIM($A3), AllStudentDetails!$H:$H, C$2) -> 5 | D3: =SUM(B3:C3) -> 11
A4: SC | B4: =COUNTIFS(AllStudentDetails!$I:$I, TRIM($A4), AllStudentDetails!$H:$H, B$2) -> 3 | C4: =COUNTIFS(AllStudentDetails!$I:$I, TRIM($A4), AllStudentDetails!$H:$H, C$2) -> 4 | D4: =SUM(B4:C4) -> 7
A5: ST | B5: =COUNTIFS(AllStudentDetails!$I:$I, TRIM($A5), AllStudentDetails!$H:$H, B$2) -> 3 | C5: =COUNTIFS(AllStudentDetails!$I:$I, TRIM($A5), AllStudentDetails!$H:$H, C$2) -> 3 | D5: =SUM(B5:C5) -> 6
A6: OBC | B6: =B7+B8 -> 11 | C6: =C7+C8 -> 7 | D6: =SUM(B6:C6) -> 18
A7: OBC(CL) | B7: =COUNTIFS(AllStudentDetails!$I:$I, TRIM($A7), AllStudentDetails!$H:$H, B$2) -> 6 | C7: =COUNTIFS(AllStudentDetails!$I:$I, TRIM($A7), AllStudentDetails!$H:$H, C$2) -> 1 | D7: =SUM(B7:C7) -> 7
A8: OBC(NCL) | B8: =COUNTIFS(AllStudentDetails!$I:$I, TRIM($A8), AllStudentDetails!$H:$H, B$2) -> 5 | C8: =COUNTIFS(AllStudentDetails!$I:$I, TRIM($A8), AllStudentDetails!$H:$H, C$2) -> 6 | D8: =SUM(B8:C8) -> 11
A9: Grand Total | B9: =SUM(B3:B5)+B6 -> 23 | C9: =SUM(C3:C5)+C6 -> 19 | D9: =SUM(D3:D5)+D6 -> 42
A13: Admission category wise Enrollment
A14: Admn Category | B14: Boy | C14: Girl | D14: Grand Total
A15: I | B15: =COUNTIFS(AllStudentDetails!$J:$J, $A15, AllStudentDetails!$H:$H, B$14) -> 3 | C15: =COUNTIFS(AllStudentDetails!$J:$J, $A15, AllStudentDetails!$H:$H, C$14) -> 1 | D15: =SUM(B15:C15) -> 4
A16: II | B16: =COUNTIFS(AllStudentDetails!$J:$J, $A16, AllStudentDetails!$H:$H, B$14) -> 2 | C16: =COUNTIFS(AllStudentDetails!$J:$J, $A16, AllStudentDetails!$H:$H, C$14) -> 2 | D16: =SUM(B16:C16) -> 4
A17: III | B17: =COUNTIFS(AllStudentDetails!$J:$J, $A17, AllStudentDetails!$H:$H, B$14) -> 0 | C17: =COUNTIFS(AllStudentDetails!$J:$J, $A17, AllStudentDetails!$H:$H, C$14) -> 0 | D17: =SUM(B17:C17) -> 0
A18: IV | B18: =COUNTIFS(AllStudentDetails!$J:$J, $A18, AllStudentDetails!$H:$H, B$14) -> 13 | C18: =COUNTIFS(AllStudentDetails!$J:$J, $A18, AllStudentDetails!$H:$H, C$14) -> 8 | D18: =SUM(B18:C18) -> 21
A19: V | B19: =COUNTIFS(AllStudentDetails!$J:$J, $A19, AllStudentDetails!$H:$H, B$14) -> 0 | C19: =COUNTIFS(AllStudentDetails!$J:$J, $A19, AllStudentDetails!$H:$H, C$14) -> 0 | D19: =SUM(B19:C19) -> 0
A20: VI | B20: =COUNTIFS(AllStudentDetails!$J:$J, $A20, AllStudentDetails!$H:$H, B$14) -> 5 | C20: =COUNTIFS(AllStudentDetails!$J:$J, $A20, AllStudentDetails!$H:$H, C$14) -> 8 | D20: =SUM(B20:C20) -> 13
A21: Grand Total | B21: =SUM(B15:B20) -> 23 | C21: =SUM(C15:C20) -> 19 | D21: =SUM(D15:D20) -> 42
A23: Monthly Enrollment Data
A24: CLASS | B24: BOYS | C24: GIRLS | D24: TOTAL | E24: SC | G24: ST | I24: OBC (CL) | K24: OBC (NCL) | M24: GEN | O24: TOTAL | R24: CAT I | T24: CAT II | V24: CAT III | X24: CAT IV | Z24: CAT V | AB24: CAT VI | AD24: TOTAL | AG24: Classwise Difference | AJ24: Social Category Difference | AM24: SGC | AN24: CWSN | AP24: Type of Disability | AQ24: RTE | AS24: BPL | AU24: Christian | AW24: Budhhist | AY24: Jain | BA24: Sikh | BC24: Parsis | BE24: MUSLIM | BG24: Hindu | BI24: TOTAL (muslim will automatically added)
B25: B | C25: G | E25: B | F25: G | G25: B | H25: G | I25: B | J25: G | K25: B | L25: G | M25: B | N25: G | O25: B | P25: G | Q25: Total | R25: B | S25: G | T25: B | U25: G | V25: B | W25: G | X25: B | Y25: G | Z25: B | AA25: G | AB25: B | AC25: G | AD25: B | AE25: G | AF25: Total | AG25: B | AH25: G | AI25: T | AJ25: B | AK25: G | AL25: T | AN25: B | AO25: G | AP25: 0 | AQ25: B | AR25: G | AS25: B | AT25: G | AU25: B | AV25: G | AW25: B | AX25: G | AY25: B | AZ25: G | BA25: B | BB25: G | BC25: B | BD25: G | BE25: B | BF25: G | BG25: B | BH25: G | BI25: B | BJ25: G | BK25: Tot
A26: VI

Sheet Dashboard

Sheet HOUSE
A1: KENDRIYA VIDYALAYA NIT AGARTALA
A2: CLASS VI (2025-26)
A4: ASHOKA HOUSE | D4: SUBHASH HOUSE
A5: BOYS | B5: GIRLS | D5: BOYS | E5: GIRLS
A6: DEBAJYOTI RUDRAPAL | B6: ALIA AKTAR | D6: AYASH DEBBARMA | E6: ARNESHA DEBNATH
A7: EMAN HUSSEN | B7: ARSALA KHATUN | D7: KUSH GUPTA | E7: CHANDRA DAS
A8: MINTU KUMAR YADAV | B8: JENISHA DEBBARMA | D8: NVK VARA PRASAD | E8: PALLABI DATTA
A9: PRITHI RAJ BHOWMIK | B9: PAYEL SANGMA | D9: ROHIT KUMAR | E9: TANEESHA PANUA
A10: SHARTHAKI RUDRA PAUL | B10: TANHA AKTER | D10: SHANTANU DAS
A13: TAGORE HOUSE | D13: RAMAN HOUSE
A14: BOYS | B14: GIRLS | D14: BOYS | E14: GIRLS
A15: ADRISH RAKSHIT | B15: ANUSHREE BEHERA | D15: ARNAV DEY | E15: ANUSHA V
A16: DEEP RAJ BHOWMIK | B16: BIPASHA DEBNATH | D16: ATIF ALAM | E16: BAISHALI DEBNATH
A17: KHAKWCHANG DEBBARMA | B17: MAITRI MAJUMDER | D17: NAVDEEP SINGH | E17: JIYA DEBBARMA
A18: OMKAR DEBNATH | B18: NISHA BHOWMIK | D18: ROHITH KRISHNA R | E18: JOYDIPA DAS
A19: RIK DEBNATH | D19: SOMYANSHU SAHOO | E19: SANVI ROY
A20: SAURAV SINHA | E20: SUPARNA DAS
A21: SUDIP ROY

Sheet MONITORS
A1: KENDRIYA VIDYALAYA NIT AGARTALA
A2: CLASS VI (2025-26)

Sheet SEATING PLAN
A1: KENDRIYA VIDYALAYA NIT AGARTALA
A2: CLASS VI (2025-26)
A3: Sitting Plan For Dates 1 to 8 of Every Month
A4: ROW 1 | D4: ROW 2 | G4: ROW 3 | J4: ROW 4
A5: 17 | B5: 8 | D5: 21 | E5: 40 | G5: 37 | H5: 29 | J5: 27 | K5: 30
A6: 1 | B6: 2 | D6: 20 | E6: 23 | G6: 10 | H6: 11 | J6: 32 | K6: 33
A7: 3 | B7: 4 | D7: 24 | E7: 25 | G7: 12 | H7: 13 | J7: 34 | K7: 35
A8: 5 | B8: 6 | D8: 26 | E8: 22 | G8: 14 | H8: 15 | J8: 36 | K8: 38
A9: 7 | B9: 9 | D9: 28 | E9: 31 | G9: 16 | H9: 18 | J9: 39 | K9: 41
G10: 19 | J10: 42
A14: KENDRIYA VIDYALAYA NIT AGARTALA
A15: CLASS VI (2025-26)
A16: Sitting Plan For Dates 9 to 16 of Every Month
A17: ROW 1 | D17: ROW 2 | G17: ROW 3 | J17: ROW 4
A18: 17 | B18: 8 | D18: 21 | E18: 40 | G18: 37 | H18: 29 | J18: 27 | K18: 30
A19: 7 | B19: 9 | D19: 28 | E19: 31 | G19: 19 | J19: 42
A20: 1 | B20: 2 | D20: 20 | E20: 23 | G20: 16 | H20: 18 | J20: 39 | K20: 41
A21: 3 | B21: 4 | D21: 24 | E21: 25 | G21: 10 | H21: 11 | J21: 32 | K21: 33
A22: 5 | B22: 6 | D22: 26 | E22: 22 | G22: 12 | H22: 13 | J22: 34 | K22: 35
G23: 14 | H23: 15 | J23: 36 | K23: 38
A27: KENDRIYA VIDYALAYA NIT AGARTALA
A28: CLASS VI (2025-26)
A29: Sitting Plan For Dates 17 to 23 of Every Month
A30: ROW 1 | D30: ROW 2 | G30: ROW 3 | J30: ROW 4
A31: 17 | B31: 8 | D31: 21 | E31: 40 | G31: 37 | H31: 29 | J31: 27 | K31: 30
A32: 5 | B32: 6 | D32: 26 | E32: 22 | G32: 14 | H32: 15 | J32: 36 | K32: 38
A33: 7 | B33: 9 | D33: 28 | E33: 31 | G33: 19 | J33: 42
A34: 1 | B34: 2 | D34: 20 | E34: 23 | G34: 16 | H34: 18 | J34: 39 | K34: 41
A35: 3 | B35: 4 | D35: 24 | E35: 25 | G35: 10 | H35: 11 | J35: 32 | K35: 33
G36: 12 | H36: 13 | J36: 34 | K36: 35
A40: KENDRIYA VIDYALAYA NIT AGARTALA
A41: CLASS VI (2025-26)
A42: Sitting Plan For Dates 24 to 30/31 of Every Month
A43: ROW 1 | D43: ROW 2 | G43: ROW 3 | J43: ROW 4
A44: 17 | B44: 8 | D44: 21 | E44: 40 | G44: 37 | H44: 29 | J44: 27 | K44: 30
A45: 3 | B45: 4 | D45: 24 | E45: 25 | G45: 12 | H45: 13 | J45: 34 | K45: 35
A46: 5 | B46: 6 | D46: 26 | E46: 22 | G46: 14 | H46: 15 | J46: 36 | K46: 38
A47: 7 | B47: 9 | D47: 28 | E47: 31 | G47: 19 | J47: 42
A48: 1 | B48: 2 | D48: 20 | E48: 23 | G48: 16 | H48: 18 | J48: 39 | K48: 41
G49: 10 | H49: 11 | J49: 32 | K49: 33

Sheet assembly duties
A1: Kendriya Vidyalaya NIT Agartala
A2: Class VI
A3: Assembly Duties (20/10/2025 to 25/10/2025)
A4: Day | B4: Date | C4: Language | D4: Command | E4: Pledge | F4: Thought | G4: Word | H4: News | I4: Special Item
A5: Monday | B5: 45950 | C5: Hindi | D5: Holiday
A6: Tuesday | B6: 45951 | C6: Hindi | D6: Shantanu | E6: Atif | F6: Sharthaki | G6: Adrish | H6: Taneesha & Bipasha | I6: Sanvi
A7: Wednesday | B7: 45952 | C7: English | D7: Holiday
A8: Thursday | B8: 45953 | C8: English | D8: Debjyoti | E8: NVK Vara | F8: Anusha | G8: Rohit Kumar | H8: Bipasha & Atif | I8: Rohit Krishna
A9: Friday | B9: 45954 | C9: English | D9: Shantanu | E9: Somyanshu | F9: Arnesha | G9: NVK Vara | H9: Taneesha & Debjyoti | I9: Ayash
A10: Saturday | B10: 45955 | C10: Sanskrit | D10: Debjyoti | E10: Sumanta | F10: Taneesha | G10: Sudip Roy | H10: Kush & Adrish | I10: ------------
